Workbook
Name CFG_WS: 'Configuración'!$C$5
Name CFG_WE: 'Configuración'!$C$6
Name CFG_DH: 'Configuración'!$C$7
Name CFG_WH: 'Configuración'!$C$8
Name CFG_BLK: 'Configuración'!$C$9
Name CFG_RATE: 'Configuración'!$C$10
Name CFG_OTRATE: 'Configuración'!$C$11
Name CFG_MAXD: 'Configuración'!$C$12
Name CFG_BRK: 'Configuración'!$C$13
Name CFG_PSTART: 'Configuración'!$C$14
Name CFG_PEND: 'Configuración'!$C$15
Name CFG_CUT: 'Configuración'!$C$16
Name CFG_WSM: 'Configuración'!$D$5
Name CFG_WEM: 'Configuración'!$D$6
Name CFG_TODAY: 'Configuración'!$D$16
Name CFG_WDAYS: 'Configuración'!$G$5:$G$11
Name FER_F: 'Configuración'!$B$21:$B$60
Name FER_N: 'Configuración'!$C$21:$C$60
Name FER_NLM: 'Configuración'!$E$21:$E$60
Name FER_NLP: 'Configuración'!$F$21:$F$60
Name FER_OBJ: 'Configuración'!$G$21:$G$60
Name L_PROY: 'Configuración'!$J$5:$J$34
Name L_EMP: 'Configuración'!$L$38:$L$39
Name L_EST: 'Configuración'!$M$38:$M$43
Name L_NA: 'Configuración'!$N$38:$N$38
Name L_BRK: 'Configuración'!$O$38:$O$40
Name L_SN: 'Configuración'!$P$38:$P$39
Name L_TFER: 'Configuración'!$W$38:$W$39
Name L_MES: 'Configuración'!$Q$38:$Q$41
Name L_MES3: 'Configuración'!$Q$39:$Q$41
Name L_MESD: 'Configuración'!$R$38:$R$41
Name L_MESH: 'Configuración'!$S$38:$S$41
Name L_SEM: 'Configuración'!$U$38:$U$51
Name L_PFILT: 'Configuración'!$V$38:$V$98
Name L_PER: 'Configuración'!$X$38:$X$41
Name R_ID: 'Registro de Horas'!$A$6:$A$5000
Name R_Fecha: 'Registro de Horas'!$B$6:$B$5000
Name R_Dia: 'Registro de Horas'!$C$6:$C$5000
Name R_Emp: 'Registro de Horas'!$D$6:$D$5000
Name R_Proy: 'Registro de Horas'!$E$6:$E$5000
Name R_Task: 'Registro de Horas'!$F$6:$F$5000
Name R_Desc: 'Registro de Horas'!$G$6:$G$5000
Name R_Ini: 'Registro de Horas'!$H$6:$H$5000
Name R_Fin: 'Registro de Horas'!$I$6:$I$5000
Name R_Brk: 'Registro de Horas'!$J$6:$J$5000
Name R_Dur: 'Registro de Horas'!$K$6:$K$5000
Name R_Nor: 'Registro de Horas'!$L$6:$L$5000
Name R_Ext: 'Registro de Horas'!$M$6:$M$5000
Name R_Blq: 'Registro de Horas'!$N$6:$N$5000
Name R_Reg: 'Registro de Horas'!$O$6:$O$5000
Name R_Val: 'Registro de Horas'!$P$6:$P$5000
Name R_Tipo: 'Registro de Horas'!$Q$6:$Q$5000
Name R_Est: 'Registro de Horas'!$R$6:$R$5000
Name R_FEnv: 'Registro de Horas'!$S$6:$S$5000
Name R_FApr: 'Registro de Horas'!$T$6:$T$5000
Name R_Obs: 'Registro de Horas'!$U$6:$U$5000
Name R_Age: 'Registro de Horas'!$V$6:$V$5000
Name R_Alert: 'Registro de Horas'!$W$6:$W$5000
Name R_Used: 'Registro de Horas'!$Y$6:$Y$5000
Name R_sMin: 'Registro de Horas'!$Z$6:$Z$5000

Sheet Dashboard
B1: Developer Time Tracking · Oct – Dic 2026
B2: Dashboard vinculado a Registro de Horas. Filtros (celdas amarillas): Mes y Proyecto aplican a los indicadores; los gráficos usan el filtro de Proyecto.
S3: Datos de los gráficos (automáticos · filtro de Proyecto)
B4: Mes ▸ | C4: Todos | F4: Proyecto ▸ | G4: Todos | J4: Período | K4: =INDEX(L_MESD,MATCH(DB_MON,L_MES,0)) -> 46296 | L4: =INDEX(L_MESH,MATCH(DB_MON,L_MES,0)) -> 46387 | N4: =IF(SUMIFS(R_Alr,R_FAll,1)+COUNTIFS(R_St,"Returned",R_FAll,1)>0,"⚠ "&(SUMIFS(R_Alr,R_FAll,1)+COUNTIFS(R_St,"Returned",R_FAll,1))&" alerta(s) proMX","✓ Sin alertas proMX") -> ⚠ 1 alerta(s) proMX | S4: Mes | T4: Malcolm | U4: proMX | V4: Normales | W4: Extras | X4: Objetivo | Y4: Trabajadas | AA4: Semana (lunes) | AB4: Malcolm | AC4: proMX | AD4: Objetivo | AE4: Aprobadas acum. | AF4: Trabajadas | AG4: Etiqueta
S5: Octubre | T5: =SUMIFS(R_HD0,R_FProj,1,R_Emp,"Malcolm",R_Fecha,">="&DATE(2026,10,1),R_Fecha,"<="&DATE(2026,10,31))+SUMIFS(R_HD1,R_FProj,1,R_Emp,"Malcolm",R_D1,">="&DATE(2026,10,1),R_D1,"<="&DATE(2026,10,31)) -> 6.333333 | U5: =SUMIFS(R_HD0,R_FProj,1,R_Emp,"proMX",R_Fecha,">="&DATE(2026,10,1),R_Fecha,"<="&DATE(2026,10,31))+SUMIFS(R_HD1,R_FProj,1,R_Emp,"proMX",R_D1,">="&DATE(2026,10,1),R_D1,"<="&DATE(2026,10,31)) -> 10.5 | V5: =SUMIFS(R_ND0,R_FProj,1,R_Fecha,">="&DATE(2026,10,1),R_Fecha,"<="&DATE(2026,10,31))+SUMIFS(R_ND1,R_FProj,1,R_D1,">="&DATE(2026,10,1),R_D1,"<="&DATE(2026,10,31)) -> 14.833333 | W5: =SUMIFS(R_XD0,R_FProj,1,R_Fecha,">="&DATE(2026,10,1),R_Fecha,"<="&DATE(2026,10,31))+SUMIFS(R_XD1,R_FProj,1,R_D1,">="&DATE(2026,10,1),R_D1,"<="&DATE(2026,10,31)) -> 2 | X5: ='Resumen Trimestral'!C12 -> 168 | Y5: =T5+U5 -> 16.833333 | AA5: 46293 | AB5: =SUMIFS(R_HD0,R_FProj,1,R_Emp,"Malcolm",R_Fecha,">="&AA5,R_Fecha,"<="&AA5+6)+SUMIFS(R_HD1,R_FProj,1,R_Emp,"Malcolm",R_D1,">="&AA5,R_D1,"<="&AA5+6) -> 0 | AC5: =SUMIFS(R_HD0,R_FProj,1,R_Emp,"proMX",R_Fecha,">="&AA5,R_Fecha,"<="&AA5+6)+SUMIFS(R_HD1,R_FProj,1,R_Emp,"proMX",R_D1,">="&AA5,R_D1,"<="&AA5+6) -> 9 | AD5: =MIN(CFG_WH,SUMIFS('Octubre 2026'!$L$9:$L$44,'Octubre 2026'!$A$9:$A$44,">="&AA5,'Octubre 2026'!$A$9:$A$44,"<="&AA5+6,'Octubre 2026'!$N$9:$N$44,"D")+SUMIFS('Noviembre 2026'!$L$9:$L$44,'Noviembre 2026'!$A$9:$A$44,">="&AA5,'Noviembre 2026'!$A$9:$A$44,"<="&AA5+6,'Noviembre 2026'!$N$9:$N$44,"D")+SUMIFS('Diciembre 2026'!$L$9:$L$44,'Diciembre 2026'!$A$9:$A$44,">="&AA5,'Diciembre 2026'!$A$9:$A$44,"<="&AA5+6,'Diciembre 2026'!$N$9:$N$44,"D")) -> 16 | AE5: =SUMIFS(R_Hval,R_St,"Approved",R_FProj,1,R_ApD,"<="&AA5+6) -> 0 | AF5: =AB5+AC5 -> 9 | AG5: 28/09
B6: TOTAL HORAS TRABAJADAS | F6: HORAS MALCOLM | J6: HORAS PROMX | N6: TIEMPO CRONOLÓGICO ÚNICO | S6: Noviembre | T6: =SUMIFS(R_HD0,R_FProj,1,R_Emp,"Malcolm",R_Fecha,">="&DATE(2026,11,1),R_Fecha,"<="&DATE(2026,11,30))+SUMIFS(R_HD1,R_FProj,1,R_Emp,"Malcolm",R_D1,">="&DATE(2026,11,1),R_D1,"<="&DATE(2026,11,30)) -> 0 | U6: =SUMIFS(R_HD0,R_FProj,1,R_Emp,"proMX",R_Fecha,">="&DATE(2026,11,1),R_Fecha,"<="&DATE(2026,11,30))+SUMIFS(R_HD1,R_FProj,1,R_Emp,"proMX",R_D1,">="&DATE(2026,11,1),R_D1,"<="&DATE(2026,11,30)) -> 0 | V6: =SUMIFS(R_ND0,R_FProj,1,R_Fecha,">="&DATE(2026,11,1),R_Fecha,"<="&DATE(2026,11,30))+SUMIFS(R_ND1,R_FProj,1,R_D1,">="&DATE(2026,11,1),R_D1,"<="&DATE(2026,11,30)) -> 0 | W6: =SUMIFS(R_XD0,R_FProj,1,R_Fecha,">="&DATE(2026,11,1),R_Fecha,"<="&DATE(2026,11,30))+SUMIFS(R_XD1,R_FProj,1,R_D1,">="&DATE(2026,11,1),R_D1,"<="&DATE(2026,11,30)) -> 0 | X6: ='Resumen Trimestral'!D12 -> 152 | Y6: =T6+U6 -> 0 | AA6: 46300 | AB6: =SUMIFS(R_HD0,R_FProj,1,R_Emp,"Malcolm",R_Fecha,">="&AA6,R_Fecha,"<="&AA6+6)+SUMIFS(R_HD1,R_FProj,1,R_Emp,"Malcolm",R_D1,">="&AA6,R_D1,"<="&AA6+6) -> 6.333333 | AC6: =SUMIFS(R_HD0,R_FProj,1,R_Emp,"proMX",R_Fecha,">="&AA6,R_Fecha,"<="&AA6+6)+SUMIFS(R_HD1,R_FProj,1,R_Emp,"proMX",R_D1,">="&AA6,R_D1,"<="&AA6+6) -> 1.5 | AD6: =MIN(CFG_WH,SUMIFS('Octubre 2026'!$L$9:$L$44,'Octubre 2026'!$A$9:$A$44,">="&AA6,'Octubre 2026'!$A$9:$A$44,"<="&AA6+6,'Octubre 2026'!$N$9:$N$44,"D")+SUMIFS('Noviembre 2026'!$L$9:$L$44,'Noviembre 2026'!$A$9:$A$44,">="&AA6,'Noviembre 2026'!$A$9:$A$44,"<="&AA6+6,'Noviembre 2026'!$N$9:$N$44,"D")+SUMIFS('Diciembre 2026'!$L$9:$L$44,'Diciembre 2026'!$A$9:$A$44,">="&AA6,'Diciembre 2026'!$A$9:$A$44,"<="&AA6+6,'Diciembre 2026'!$N$9:$N$44,"D")) -> 40 | AE6: =SUMIFS(R_Hval,R_St,"Approved",R_FProj,1,R_ApD,"<="&AA6+6) -> 6 | AF6: =AB6+AC6 -> 7.833333 | AG6: 05/10
B7: =SUMIFS(R_Hcnt,R_FAll,1) -> 16.833333 | F7: =SUMIFS(R_Hcnt,R_Emp,"Malcolm",R_FAll,1) -> 6.333333 | J7: =SUMIFS(R_Hcnt,R_Emp,"proMX",R_FAll,1) -> 10.5 | N7: =SUMIFS(R_Hcnt,R_FAll,1)-SUMIFS(R_XOvH,R_FAll,1) -> 16.833333 | S7: Diciembre | T7: =SUMIFS(R_HD0,R_FProj,1,R_Emp,"Malcolm",R_Fecha,">="&DATE(2026,12,1),R_Fecha,"<="&DATE(2026,12,31))+SUMIFS(R_HD1,R_FProj,1,R_Emp,"Malcolm",R_D1,">="&DATE(2026,12,1),R_D1,"<="&DATE(2026,12,31)) -> 0 | U7: =SUMIFS(R_HD0,R_FProj,1,R_Emp,"proMX",R_Fecha,">="&DATE(2026,12,1),R_Fecha,"<="&DATE(2026,12,31))+SUMIFS(R_HD1,R_FProj,1,R_Emp,"proMX",R_D1,">="&DATE(2026,12,1),R_D1,"<="&DATE(2026,12,31)) -> 0 | V7: =SUMIFS(R_ND0,R_FProj,1,R_Fecha,">="&DATE(2026,12,1),R_Fecha,"<="&DATE(2026,12,31))+SUMIFS(R_ND1,R_FProj,1,R_D1,">="&DATE(2026,12,1),R_D1,"<="&DATE(2026,12,31)) -> 0 | W7: =SUMIFS(R_XD0,R_FProj,1,R_Fecha,">="&DATE(2026,12,1),R_Fecha,"<="&DATE(2026,12,31))+SUMIFS(R_XD1,R_FProj,1,R_D1,">="&DATE(2026,12,1),R_D1,"<="&DATE(2026,12,31)) -> 0 | X7: ='Resumen Trimestral'!E12 -> 176 | Y7: =T7+U7 -> 0 | AA7: 46307 | AB7: =SUMIFS(R_HD0,R_FProj,1,R_Emp,"Malcolm",R_Fecha,">="&AA7,R_Fecha,"<="&AA7+6)+SUMIFS(R_HD1,R_FProj,1,R_Emp,"Malcolm",R_D1,">="&AA7,R_D1,"<="&AA7+6) -> 0 | AC7: =SUMIFS(R_HD0,R_FProj,1,R_Emp,"proMX",R_Fecha,">="&AA7,R_Fecha,"<="&AA7+6)+SUMIFS(R_HD1,R_FProj,1,R_Emp,"proMX",R_D1,">="&AA7,R_D1,"<="&AA7+6) -> 0 | AD7: =MIN(CFG_WH,SUMIFS('Octubre 2026'!$L$9:$L$44,'Octubre 2026'!$A$9:$A$44,">="&AA7,'Octubre 2026'!$A$9:$A$44,"<="&AA7+6,'Octubre 2026'!$N$9:$N$44,"D")+SUMIFS('Noviembre 2026'!$L$9:$L$44,'Noviembre 2026'!$A$9:$A$44,">="&AA7,'Noviembre 2026'!$A$9:$A$44,"<="&AA7+6,'Noviembre 2026'!$N$9:$N$44,"D")+SUMIFS('Diciembre 2026'!$L$9:$L$44,'Diciembre 2026'!$A$9:$A$44,">="&AA7,'Diciembre 2026'!$A$9:$A$44,"<="&AA7+6,'Diciembre 2026'!$N$9:$N$44,"D")) -> 32 | AE7: =SUMIFS(R_Hval,R_St,"Approved",R_FProj,1,R_ApD,"<="&AA7+6) -> 6 | AF7: =AB7+AC7 -> 0 | AG7: 12/10
AA8: 46314 | AB8: =SUMIFS(R_HD0,R_FProj,1,R_Emp,"Malcolm",R_Fecha,">="&AA8,R_Fecha,"<="&AA8+6)+SUMIFS(R_HD1,R_FProj,1,R_Emp,"Malcolm",R_D1,">="&AA8,R_D1,"<="&AA8+6) -> 0 | AC8: =SUMIFS(R_HD0,R_FProj,1,R_Emp,"proMX",R_Fecha,">="&AA8,R_Fecha,"<="&AA8+6)+SUMIFS(R_HD1,R_FProj,1,R_Emp,"proMX",R_D1,">="&AA8,R_D1,"<="&AA8+6) -> 0 | AD8: =MIN(CFG_WH,SUMIFS('Octubre 2026'!$L$9:$L$44,'Octubre 2026'!$A$9:$A$44,">="&AA8,'Octubre 2026'!$A$9:$A$44,"<="&AA8+6,'Octubre 2026'!$N$9:$N$44,"D")+SUMIFS('Noviembre 2026'!$L$9:$L$44,'Noviembre 2026'!$A$9:$A$44,">="&AA8,'Noviembre 2026'!$A$9:$A$44,"<="&AA8+6,'Noviembre 2026'!$N$9:$N$44,"D")+SUMIFS('Diciembre 2026'!$L$9:$L$44,'Diciembre 2026'!$A$9:$A$44,">="&AA8,'Diciembre 2026'!$A$9:$A$44,"<="&AA8+6,'Diciembre 2026'!$N$9:$N$44,"D")) -> 40 | AE8: =SUMIFS(R_Hval,R_St,"Approved",R_FProj,1,R_ApD,"<="&AA8+6) -> 6 | AF8: =AB8+AC8 -> 0 | AG8: 19/10
B9: Imputadas a ambas empresas | F9: Registros válidos | J9: Válidas, sin Cancelled | N9: ="Superposición Malcolm/proMX: "&FIXED(SUMIFS(R_XOvH,R_FAll,1),2)&" h" -> Superposición Malcolm/proMX: 0.00 h | AA9: 46321 | AB9: =SUMIFS(R_HD0,R_FProj,1,R_Emp,"Malcolm",R_Fecha,">="&AA9,R_Fecha,"<="&AA9+6)+SUMIFS(R_HD1,R_FProj,1,R_Emp,"Malcolm",R_D1,">="&AA9,R_D1,"<="&AA9+6) -> 0 | AC9: =SUMIFS(R_HD0,R_FProj,1,R_Emp,"proMX",R_Fecha,">="&AA9,R_Fecha,"<="&AA9+6)+SUMIFS(R_HD1,R_FProj,1,R_Emp,"proMX",R_D1,">="&AA9,R_D1,"<="&AA9+6) -> 0 | AD9: =MIN(CFG_WH,SUMIFS('Octubre 2026'!$L$9:$L$44,'Octubre 2026'!$A$9:$A$44,">="&AA9,'Octubre 2026'!$A$9:$A$44,"<="&AA9+6,'Octubre 2026'!$N$9:$N$44,"D")+SUMIFS('Noviembre 2026'!$L$9:$L$44,'Noviembre 2026'!$A$9:$A$44,">="&AA9,'Noviembre 2026'!$A$9:$A$44,"<="&AA9+6,'Noviembre 2026'!$N$9:$N$44,"D")+SUMIFS('Diciembre 2026'!$L$9:$L$44,'Diciembre 2026'!$A$9:$A$44,">="&AA9,'Diciembre 2026'!$A$9:$A$44,"<="&AA9+6,'Diciembre 2026'!$N$9:$N$44,"D")) -> 40 | AE9: =SUMIFS(R_Hval,R_St,"Approved",R_FProj,1,R_ApD,"<="&AA9+6) -> 6 | AF9: =AB9+AC9 -> 0 | AG9: 26/10
S10: Estado proMX | T10: Horas | AA10: 46328 | AB10: =SUMIFS(R_HD0,R_FProj,1,R_Emp,"Malcolm",R_Fecha,">="&AA10,R_Fecha,"<="&AA10+6)+SUMIFS(R_HD1,R_FProj,1,R_Emp,"Malcolm",R_D1,">="&AA10,R_D1,"<="&AA10+6) -> 0 | AC10: =SUMIFS(R_HD0,R_FProj,1,R_Emp,"proMX",R_Fecha,">="&AA10,R_Fecha,"<="&AA10+6)+SUMIFS(R_HD1,R_FProj,1,R_Emp,"proMX",R_D1,">="&AA10,R_D1,"<="&AA10+6) -> 0 | AD10: =MIN(CFG_WH,SUMIFS('Octubre 2026'!$L$9:$L$44,'Octubre 2026'!$A$9:$A$44,">="&AA10,'Octubre 2026'!$A$9:$A$44,"<="&AA10+6,'Octubre 2026'!$N$9:$N$44,"D")+SUMIFS('Noviembre 2026'!$L$9:$L$44,'Noviembre 2026'!$A$9:$A$44,">="&AA10,'Noviembre 2026'!$A$9:$A$44,"<="&AA10+6,'Noviembre 2026'!$N$9:$N$44,"D")+SUMIFS('Diciembre 2026'!$L$9:$L$44,'Diciembre 2026'!$A$9:$A$44,">="&AA10,'Diciembre 2026'!$A$9:$A$44,"<="&AA10+6,'Diciembre 2026'!$N$9:$N$44,"D")) -> 40 | AE10: =SUMIFS(R_Hval,R_St,"Approved",R_FProj,1,R_ApD,"<="&AA10+6) -> 6 | AF10: =AB10+AC10 -> 0 | AG10: 02/11
B11: HORAS NORMALES | F11: HORAS EXTRAS | J11: HORAS OBJETIVO | N11: HORAS DRAFT | S11: Draft | T11: =SUMIFS(R_Hval,R_St,"Draft",R_FProj,1) -> 1.5 | AA11: 46335 | AB11: =SUMIFS(R_HD0,R_FProj,1,R_Emp,"Malcolm",R_Fecha,">="&AA11,R_Fecha,"<="&AA11+6)+SUMIFS(R_HD1,R_FProj,1,R_Emp,"Malcolm",R_D1,">="&AA11,R_D1,"<="&AA11+6) -> 0 | AC11: =SUMIFS(R_HD0,R_FProj,1,R_Emp,"proMX",R_Fecha,">="&AA11,R_Fecha,"<="&AA11+6)+SUMIFS(R_HD1,R_FProj,1,R_Emp,"proMX",R_D1,">="&AA11,R_D1,"<="&AA11+6) -> 0 | AD11: =MIN(CFG_WH,SUMIFS('Octubre 2026'!$L$9:$L$44,'Octubre 2026'!$A$9:$A$44,">="&AA11,'Octubre 2026'!$A$9:$A$44,"<="&AA11+6,'Octubre 2026'!$N$9:$N$44,"D")+SUMIFS('Noviembre 2026'!$L$9:$L$44,'Noviembre 2026'!$A$9:$A$44,">="&AA11,'Noviembre 2026'!$A$9:$A$44,"<="&AA11+6,'Noviembre 2026'!$N$9:$N$44,"D")+SUMIFS('Diciembre 2026'!$L$9:$L$44,'Diciembre 2026'!$A$9:$A$44,">="&AA11,'Diciembre 2026'!$A$9:$A$44,"<="&AA11+6,'Diciembre 2026'!$N$9:$N$44,"D")) -> 32 | AE11: =SUMIFS(R_Hval,R_St,"Approved",R_FProj,1,R_ApD,"<="&AA11+6) -> 6 | AF11: =AB11+AC11 -> 0 | AG11: 09/11
B12: =SUMIFS(R_NorH,R_FAll,1) -> 14.833333 | F12: =SUMIFS(R_ExtH,R_FAll,1) -> 2 | J12: =IF(DB_MON="Todos",'Resumen Trimestral'!F12,INDEX('Resumen Trimestral'!C12:E12,MATCH(DB_MON,L_MES3,0))) -> 496 | N12: =SUMIFS(R_Hval,R_St,"Draft",R_FAll,1) -> 1.5 | S12: Submitted | T12: =SUMIFS(R_Hval,R_St,"Submitted",R_FProj,1) -> 3 | AA12: 46342 | AB12: =SUMIFS(R_HD0,R_FProj,1,R_Emp,"Malcolm",R_Fecha,">="&AA12,R_Fecha,"<="&AA12+6)+SUMIFS(R_HD1,R_FProj,1,R_Emp,"Malcolm",R_D1,">="&AA12,R_D1,"<="&AA12+6) -> 0 | AC12: =SUMIFS(R_HD0,R_FProj,1,R_Emp,"proMX",R_Fecha,">="&AA12,R_Fecha,"<="&AA12+6)+SUMIFS(R_HD1,R_FProj,1,R_Emp,"proMX",R_D1,">="&AA12,R_D1,"<="&AA12+6) -> 0 | AD12: =MIN(CFG_WH,SUMIFS('Octubre 2026'!$L$9:$L$44,'Octubre 2026'!$A$9:$A$44,">="&AA12,'Octubre 2026'!$A$9:$A$44,"<="&AA12+6,'Octubre 2026'!$N$9:$N$44,"D")+SUMIFS('Noviembre 2026'!$L$9:$L$44,'Noviembre 2026'!$A$9:$A$44,">="&AA12,'Noviembre 2026'!$A$9:$A$44,"<="&AA12+6,'Noviembre 2026'!$N$9:$N$44,"D")+SUMIFS('Diciembre 2026'!$L$9:$L$44,'Diciembre 2026'!$A$9:$A$44,">="&AA12,'Diciembre 2026'!$A$9:$A$44,"<="&AA12+6,'Diciembre 2026'!$N$9:$N$44,"D")) -> 40 | AE12: =SUMIFS(R_Hval,R_St,"Approved",R_FProj,1,R_ApD,"<="&AA12+6) -> 6 | AF12: =AB12+AC12 -> 0 | AG12: 16/11
S13: Approved | T13: =SUMIFS(R_Hval,R_St,"Approved",R_FProj,1) -> 6 | AA13: 46349 | AB13: =SUMIFS(R_HD0,R_FProj,1,R_Emp,"Malcolm",R_Fecha,">="&AA13,R_Fecha,"<="&AA13+6)+SUMIFS(R_HD1,R_FProj,1,R_Emp,"Malcolm",R_D1,">="&AA13,R_D1,"<="&AA13+6) -> 0 | AC13: =SUMIFS(R_HD0,R_FProj,1,R_Emp,"proMX",R_Fecha,">="&AA13,R_Fecha,"<="&AA13+6)+SUMIFS(R_HD1,R_FProj,1,R_Emp,"proMX",R_D1,">="&AA13,R_D1,"<="&AA13+6) -> 0 | AD13: =MIN(CFG_WH,SUMIFS('Octubre 2026'!$L$9:$L$44,'Octubre 2026'!$A$9:$A$44,">="&AA13,'Octubre 2026'!$A$9:$A$44,"<="&AA13+6,'Octubre 2026'!$N$9:$N$44,"D")+SUMIFS('Noviembre 2026'!$L$9:$L$44,'Noviembre 2026'!$A$9:$A$44,">="&AA13,'Noviembre 2026'!$A$9:$A$44,"<="&AA13+6,'Noviembre 2026'!$N$9:$N$44,"D")+SUMIFS('Diciembre 2026'!$L$9:$L$44,'Diciembre 2026'!$A$9:$A$44,">="&AA13,'Diciembre 2026'!$A$9:$A$44,"<="&AA13+6,'Diciembre 2026'!$N$9:$N$44,"D")) -> 32 | AE13: =SUMIFS(R_Hval,R_St,"Approved",R_FProj,1,R_ApD,"<="&AA13+6) -> 6 | AF13: =AB13+AC13 -> 0 | AG13: 23/11
B14: Dentro del horario laboral | F14: Fuera de horario / días no laborables | J14: ="Cumplimiento (todos los proyectos): "&FIXED(IFERROR(100*SUMIFS(R_Hcnt,R_FMon,1)/J12,0),0)&"%" -> Cumplimiento (todos los proyectos): 3% | N14: proMX · registradas, sin enviar | S14: Returned | T14: =SUMIFS(R_Hval,R_St,"Returned",R_FProj,1) -> 0 | AA14: 46356 | AB14: =SUMIFS(R_HD0,R_FProj,1,R_Emp,"Malcolm",R_Fecha,">="&AA14,R_Fecha,"<="&AA14+6)+SUMIFS(R_HD1,R_FProj,1,R_Emp,"Malcolm",R_D1,">="&AA14,R_D1,"<="&AA14+6) -> 0 | AC14: =SUMIFS(R_HD0,R_FProj,1,R_Emp,"proMX",R_Fecha,">="&AA14,R_Fecha,"<="&AA14+6)+SUMIFS(R_HD1,R_FProj,1,R_Emp,"proMX",R_D1,">="&AA14,R_D1,"<="&AA14+6) -> 0 | AD14: =MIN(CFG_WH,SUMIFS('Octubre 2026'!$L$9:$L$44,'Octubre 2026'!$A$9:$A$44,">="&AA14,'Octubre 2026'!$A$9:$A$44,"<="&AA14+6,'Octubre 2026'!$N$9:$N$44,"D")+SUMIFS('Noviembre 2026'!$L$9:$L$44,'Noviembre 2026'!$A$9:$A$44,">="&AA14,'Noviembre 2026'!$A$9:$A$44,"<="&AA14+6,'Noviembre 2026'!$N$9:$N$44,"D")+SUMIFS('Diciembre 2026'!$L$9:$L$44,'Diciembre 2026'!$A$9:$A$44,">="&AA14,'Diciembre 2026'!$A$9:$A$44,"<="&AA14+6,'Diciembre 2026'!$N$9:$N$44,"D")) -> 40 | AE14: =SUMIFS(R_Hval,R_St,"Approved",R_FProj,1,R_ApD,"<="&AA14+6) -> 6 | AF14: =AB14+AC14 -> 0 | AG14: 30/11
S15: Recall Requested | T15: =SUMIFS(R_Hval,R_St,"Recall Requested",R_FProj,1) -> 0 | AA15: 46363 | AB15: =SUMIFS(R_HD0,R_FProj,1,R_Emp,"Malcolm",R_Fecha,">="&AA15,R_Fecha,"<="&AA15+6)+SUMIFS(R_HD1,R_FProj,1,R_Emp,"Malcolm",R_D1,">="&AA15,R_D1,"<="&AA15+6) -> 0 | AC15: =SUMIFS(R_HD0,R_FProj,1,R_Emp,"proMX",R_Fecha,">="&AA15,R_Fecha,"<="&AA15+6)+SUMIFS(R_HD1,R_FProj,1,R_Emp,"proMX",R_D1,">="&AA15,R_D1,"<="&AA15+6) -> 0 | AD15: =MIN(CFG_WH,SUMIFS('Octubre 2026'!$L$9:$L$44,'Octubre 2026'!$A$9:$A$44,">="&AA15,'Octubre 2026'!$A$9:$A$44,"<="&AA15+6,'Octubre 2026'!$N$9:$N$44,"D")+SUMIFS('Noviembre 2026'!$L$9:$L$44,'Noviembre 2026'!$A$9:$A$44,">="&AA15,'Noviembre 2026'!$A$9:$A$44,"<="&AA15+6,'Noviembre 2026'!$N$9:$N$44,"D")+SUMIFS('Diciembre 2026'!$L$9:$L$44,'Diciembre 2026'!$A$9:$A$44,">="&AA15,'Diciembre 2026'!$A$9:$A$44,"<="&AA15+6,'Diciembre 2026'!$N$9:$N$44,"D")) -> 40 | AE15: =SUMIFS(R_Hval,R_St,"Approved",R_FProj,1,R_ApD,"<="&AA15+6) -> 6 | AF15: =AB15+AC15 -> 0 | AG15: 07/12
B16: HORAS SUBMITTED | F16: HORAS APPROVED | J16: PENDIENTES DE APROBACIÓN | N16: BLOQUES PROMX APROBADOS | S16: Cancelled | T16: =SUMIFS(R_Hval,R_St,"Cancelled",R_FProj,1) -> 0 | AA16: 46370 | AB16: =SUMIFS(R_HD0,R_FProj,1,R_Emp,"Malcolm",R_Fecha,">="&AA16,R_Fecha,"<="&AA16+6)+SUMIFS(R_HD1,R_FProj,1,R_Emp,"Malcolm",R_D1,">="&AA16,R_D1,"<="&AA16+6) -> 0 | AC16: =SUMIFS(R_HD0,R_FProj,1,R_Emp,"proMX",R_Fecha,">="&AA16,R_Fecha,"<="&AA16+6)+SUMIFS(R_HD1,R_FProj,1,R_Emp,"proMX",R_D1,">="&AA16,R_D1,"<="&AA16+6) -> 0 | AD16: =MIN(CFG_WH,SUMIFS('Octubre 2026'!$L$9:$L$44,'Octubre 2026'!$A$9:$A$44,">="&AA16,'Octubre 2026'!$A$9:$A$44,"<="&AA16+6,'Octubre 2026'!$N$9:$N$44,"D")+SUMIFS('Noviembre 2026'!$L$9:$L$44,'Noviembre 2026'!$A$9:$A$44,">="&AA16,'Noviembre 2026'!$A$9:$A$44,"<="&AA16+6,'Noviembre 2026'!$N$9:$N$44,"D")+SUMIFS('Diciembre 2026'!$L$9:$L$44,'Diciembre 2026'!$A$9:$A$44,">="&AA16,'Diciembre 2026'!$A$9:$A$44,"<="&AA16+6,'Diciembre 2026'!$N$9:$N$44,"D")) -> 40 | AE16: =SUMIFS(R_Hval,R_St,"Approved",R_FProj,1,R_ApD,"<="&AA16+6) -> 6 | AF16: =AB16+AC16 -> 0 | AG16: 14/12
B17: =SUMIFS(R_Hval,R_St,"Submitted",R_FAll,1) -> 3 | F17: =SUMIFS(R_Hval,R_St,"Approved",R_FAll,1) -> 6 | J17: =SUMIFS(R_Hval,R_St,"Submitted",R_FAll,1)+SUMIFS(R_Hval,R_St,"Recall Requested",R_FAll,1) -> 3 | N17: =SUMIFS(R_BlkV,R_St,"Approved",R_FAll,1) -> 12 | AA17: 46377 | AB17: =SUMIFS(R_HD0,R_FProj,1,R_Emp,"Malcolm",R_Fecha,">="&AA17,R_Fecha,"<="&AA17+6)+SUMIFS(R_HD1,R_FProj,1,R_Emp,"Malcolm",R_D1,">="&AA17,R_D1,"<="&AA17+6) -> 0 | AC17: =SUMIFS(R_HD0,R_FProj,1,R_Emp,"proMX",R_Fecha,">="&AA17,R_Fecha,"<="&AA17+6)+SUMIFS(R_HD1,R_FProj,1,R_Emp,"proMX",R_D1,">="&AA17,R_D1,"<="&AA17+6) -> 0 | AD17: =MIN(CFG_WH,SUMIFS('Octubre 2026'!$L$9:$L$44,'Octubre 2026'!$A$9:$A$44,">="&AA17,'Octubre 2026'!$A$9:$A$44,"<="&AA17+6,'Octubre 2026'!$N$9:$N$44,"D")+SUMIFS('Noviembre 2026'!$L$9:$L$44,'Noviembre 2026'!$A$9:$A$44,">="&AA17,'Noviembre 2026'!$A$9:$A$44,"<="&AA17+6,'Noviembre 2026'!$N$9:$N$44,"D")+SUMIFS('Diciembre 2026'!$L$9:$L$44,'Diciembre 2026'!$A$9:$A$44,">="&AA17,'Diciembre 2026'!$A$9:$A$44,"<="&AA17+6,'Diciembre 2026'!$N$9:$N$44,"D")) -> 32 | AE17: =SUMIFS(R_Hval,R_St,"Approved",R_FProj,1,R_ApD,"<="&AA17+6) -> 6 | AF17: =AB17+AC17 -> 0 | AG17: 21/12
AA18: 46384 | AB18: =SUMIFS(R_HD0,R_FProj,1,R_Emp,"Malcolm",R_Fecha,">="&AA18,R_Fecha,"<="&AA18+6)+SUMIFS(R_HD1,R_FProj,1,R_Emp,"Malcolm",R_D1,">="&AA18,R_D1,"<="&AA18+6) -> 0 | AC18: =SUMIFS(R_HD0,R_FProj,1,R_Emp,"proMX",R_Fecha,">="&AA18,R_Fecha,"<="&AA18+6)+SUMIFS(R_HD1,R_FProj,1,R_Emp,"proMX",R_D1,">="&AA18,R_D1,"<="&AA18+6) -> 0 | AD18: =MIN(CFG_WH,SUMIFS('Octubre 2026'!$L$9:$L$44,'Octubre 2026'!$A$9:$A$44,">="&AA18,'Octubre 2026'!$A$9:$A$44,"<="&AA18+6,'Octubre 2026'!$N$9:$N$44,"D")+SUMIFS('Noviembre 2026'!$L$9:$L$44,'Noviembre 2026'!$A$9:$A$44,">="&AA18,'Noviembre 2026'!$A$9:$A$44,"<="&AA18+6,'Noviembre 2026'!$N$9:$N$44,"D")+SUMIFS('Diciembre 2026'!$L$9:$L$44,'Diciembre 2026'!$A$9:$A$44,">="&AA18,'Diciembre 2026'!$A$9:$A$44,"<="&AA18+6,'Diciembre 2026'!$N$9:$N$44,"D")) -> 32 | AE18: =SUMIFS(R_Hval,R_St,"Approved",R_FProj,1,R_ApD,"<="&AA18+6) -> 6 | AF18: =AB18+AC18 -> 0 | AG18: 28/12
B19: proMX · enviadas, esperando aprobación | F19: proMX · aprobadas | J19: ="Submitted + Recall · Pend. envío: "&FIXED(SUMIFS(R_Hval,R_St,"Draft",R_FAll,1)+SUMIFS(R_Hval,R_St,"Returned",R_FAll,1),2)&" h" -> Submitted + Recall · Pend. envío: 1.50 h | N19: ="% aprobación: "&FIXED(IFERROR(100*SUMIFS(R_Hval,R_St,"Approved",R_FAll,1)/(SUMIFS(R_Hval,R_St,"Approved",R_FAll,1)+SUMIFS(R_Hval,R_St,"Submitted",R_FAll,1)+SUMIFS(R_Hval,R_St,"Returned",R_FAll,1)+SUMIFS(R_Hval,R_St,"Recall Requested",R_FAll,1)),0),1)&"%" -> % aprobación: 66.7%
B21: USD APROBADOS | F21: USD COBRADOS | J21: USD PENDIENTES DE COBRO | N21: REGISTROS A REVISAR
B22: =SUMIFS(R_USD,R_St,"Approved",R_FAll,1) -> 300 | F22: =IF(DB_MON="Todos",SUM(PAY_AMT),SUMIFS(PAY_AMT,PAY_PER,DB_MON)) -> 200 | J22: =SUMIFS(R_USD,R_St,"Approved",R_FMon,1)-IF(DB_MON="Todos",SUM(PAY_AMT),SUMIFS(PAY_AMT,PAY_PER,DB_MON)) -> 100 | N22: =COUNTIFS(R_Used,1,R_Valid,0) -> 0
B24: Horas aprobadas × tarifa | F24: Pagos registrados (no filtra proyecto) | J24: Aprobado − cobrado (todos los proyectos) | N24: Inválidos: excluidos de los totales

Sheet Registro de Horas
B1: 🕒 Registro de Horas
B2: Carga diaria. Una fila por tarea/tramo. Malcolm y proMX son registros independientes: nunca se copian entre empresas.
B3: Leyenda: | C3: Editable | E3: Fórmula (protegida) | G3: Malcolm: precisión al minuto. proMX: inicio, fin y duración en bloques de 30 min. Cruce de medianoche: hora fin menor que hora inicio. | P3: Registros a revisar: | Q3: =COUNTIFS(R_Used,1,R_Valid,0) -> 0 | R3: Horas Malcolm / proMX: | S3: =SUMIFS(R_Hcnt,R_Emp,"Malcolm") -> 6.333333 | T3: =SUMIFS(R_Hcnt,R_Emp,"proMX") -> 10.5
A5: ID | B5: Fecha | C5: Día | D5: Empresa | E5: Proyecto | F5: Task ID | G5: Descripción | H5: Hora inicio | I5: Hora fin | J5: Descanso (min) | K5: Duración real (h) | L5: Horas normales | M5: Horas extras | N5: Bloques proMX | O5: Horas registrables proMX | P5: Validación | Q5: Tipo de día | R5: Estado proMX | S5: Fecha envío | T5: Fecha aprobación | U5: Observaciones | V5: Antigüedad (días) | W5: Alerta | Y5: aux_Used | Z5: aux_sMin | AA5: aux_eMin | AB5: aux_TOK | AC5: aux_Cross | AD5: aux_Gross | AE5: aux_BrkRaw | AF5: aux_Beff | AG5: aux_Net | AH5: aux_WD0 | AI5: aux_WD1 | AJ5: aux_G1 | AK5: aux_N1 | AL5: aux_N2 | AM5: aux_NG | AN5: aux_BN | AO5: aux_BEx | AP5: aux_NormM | AQ5: aux_ExtM | AR5: aux_NormD0 | AS5: aux_ExtD0 | AT5: aux_D1 | AU5: aux_NC | AV5: aux_Dup | AW5: aux_SAbs | AX5: aux_EAbs | AY5: aux_OKey | AZ5: aux_SameOv | BA5: aux_CrossOv | BB5: aux_BlkOK | BC5: aux_Err | BD5: aux_Valid | BE5: aux_Cnt | BF5: aux_St | BG5: aux_Hval | BH5: aux_Hcnt | BI5: aux_NorH | BJ5: aux_ExtH | BK5: aux_HD0 | BL5: aux_HD1 | BM5: aux_ND0 | BN5: aux_ND1 | BO5: aux_XD0 | BP5: aux_XD1 | BQ5: aux_SN | BR5: aux_EN | BS5: aux_XOvH | BT5: aux_USD | BU5: aux_BlkV | BV5: aux_ApD | BW5: aux_FMon | BX5: aux_FProj | BY5: aux_FAll | BZ5: aux_Label | CA5: aux_PSeq | CB5: aux_PSeqM | CC5: aux_PSeqP | CD5: aux_TSeqM | CE5: aux_TSeqP | CF5: aux_PendSeq | CG5: aux_StCode | CH5: aux_Alr
A6: =IF(Y6=1,ROW()-5,"") -> 1 | B6: 46296 | C6: =IF(ISNUMBER(B6),CHOOSE(WEEKDAY(B6,2),"Lun","Mar","Mié","Jue","Vie","Sáb","Dom"),"") -> Jue | D6: proMX | E6: Portal Cliente | F6: PMX-203 | G6: [EJEMPLO] Desarrollo de funcionalidad | H6: 0.375 | I6: 0.54166667 | J6: 0 | K6: =IF(AB6=1,ROUND(AG6/60,4),"") -> 4 | L6: =IF(BD6=1,ROUND(AP6/60,4),"") -> 4 | M6: =IF(BD6=1,ROUND(AQ6/60,4),"") -> 0 | N6: =IF(AND(D6="proMX",AB6=1),ROUND(AG6/CFG_BLK,2),"") -> 8 | O6: =IF(D6="proMX",IF(BD6=1,ROUND(AG6/60,4),0),"") -> 4 | P6: =IF(Y6=0,"",IF(BD6=1,"OK",IF(D6="proMX","Revisar bloques: ","Revisar: ")&BC6)) -> OK | Q6: =IF(NOT(ISNUMBER(B6)),"",IF(COUNTIFS(FER_F,INT(B6))>0,"Feriado"&IF(AH6=1," (laborable)"," (no laborable)"),IF(AH6=1,"Laborable",IF(WEEKDAY(B6,2)>5,"Fin de semana","No laborable")))) -> Laborable | R6: Approved | S6: 46297 | T6: 46300 | U6: EJEMPLO – se puede borrar | V6: =IF(AND(D6="proMX",OR(R6="Submitted",R6="Recall Requested"),ISNUMBER(S6)),CFG_TODAY-INT(S6),"") | W6: =IF(BD6=0,"",IF(BA6>0,"⚠ Se superpone con un registro de la otra empresa",IF(D6="Malcolm",IF(COUNTA(R6,S6,T6)>0,"Estado/fechas proMX se ignoran en Malcolm",""),IF(BF6="Cancelled","Cancelado: excluido de totales",IF(R6="","Sin estado: se trata como Draft",IF(BF6="Submitted",IF(ISNUMBER(V6),IF(V6>CFG_MAXD,"⚠ "&V6&" días en Submitted (máx. "&CFG_MAXD&")",""),"Falta fecha de envío"),IF(BF6="Returned","⚠ Devuelto: corregir y reenviar",IF(BF6="Recall Requested","Retirada solicitada: pendiente",IF(AND(BF6="Approved",NOT(ISNUMBER(T6))),"Falta fecha de aprobación",IF(AND(ISNUMBER(S6),ISNUMBER(T6),T6<S6),"Aprobación anterior al envío",""))))))))) | Y6: =IF(COUNTA(B6,D6,E6,F6,G6,H6,I6,J6,R6,S6,T6)>0,1,0) -> 1 | Z6: =IF(AND(ISNUMBER(H6),H6>=0,H6<1),ROUND(H6*1440,0),"") -> 540 | AA6: =IF(AND(ISNUMBER(I6),I6>=0,I6<1),ROUND(I6*1440,0),"") -> 780 | AB6: =IF(AND(ISNUMBER(B6),D6<>"",ISNUMBER(Z6),ISNUMBER(AA6)),IF(Z6=AA6,0,1),0) -> 1 | AC6: =IF(AB6=1,IF(AA6<Z6,1,0),0) -> 0 | AD6: =IF(AB6=1,IF(AC6=1,1440-Z6+AA6,AA6-Z6),0) -> 240 | AE6: =IF(J6="",0,IF(ISNUMBER(J6),J6,-1)) -> 0 | AF6: =MIN(MAX(0,AE6),AD6) -> 0 | AG6: =MAX(0,AD6-MAX(0,AE6)) -> 240 | AH6: =IF(ISNUMBER(B6),IF(AND(INDEX(CFG_WDAYS,WEEKDAY(INT(B6),2))="Sí",IF(D6="proMX",COUNTIFS(FER_F,INT(B6),FER_NLP,"Sí"),COUNTIFS(FER_F,INT(B6),FER_NLM,"Sí"))=0),1,0),0) -> 1 | AI6: =IF(AC6=1,IF(AND(INDEX(CFG_WDAYS,WEEKDAY(INT(B6)+1,2))="Sí",IF(D6="proMX",COUNTIFS(FER_F,INT(B6)+1,FER_NLP,"Sí"),COUNTIFS(FER_F,INT(B6)+1,FER_NLM,"Sí"))=0),1,0),0) -> 0 | AJ6: =IF(AC6=1,1440-Z6,AD6) -> 240 | AK6: =IF(AND(AB6=1,AH6=1),MAX(0,MIN(IF(AC6=1,1440,AA6),CFG_WEM)-MAX(Z6,CFG_WSM)),0) -> 240 | AL6: =IF(AND(AC6=1,AI6=1),MAX(0,MIN(AA6,CFG_WEM)-CFG_WSM),0) -> 0 | AM6: =AK6+AL6 -> 240 | AN6: =IF(CFG_BRK="Proporcional",IF(AD6=0,0,AF6*AM6/AD6),IF(CFG_BRK="Extras primero",MIN(AM6,MAX(0,AF6-(AD6-AM6))),MIN(AF6,AM6))) -> 0 | AO6: =AF6-AN6 -> 0 | AP6: =AM6-AN6 -> 240 | AQ6: =AD6-AM6-AO6 -> 0 | AR6: =IF(AM6=0,0,AK6-AN6*AK6/AM6) -> 240 | AS6: =IF(AD6-AM6=0,0,(AJ6-AK6)-AO6*(AJ6-AK6)/(AD6-AM6)) -> 0 | AT6: =IF(AC6=1,INT(B6)+1,"") | AU6: =IF(AND(D6="proMX",R6="Cancelled"),0,1) -> 1 | AV6: =IF(AND(AB6=1,AU6=1),IF(COUNTIFS($D$5:D5,D6,$B$5:B5,B6,$Z$5:Z5,Z6,$AA$5:AA5,AA6,$F$5:F5,F6&"",$AU$5:AU5,1)>0,1,0),0) -> 0 | AW6: =IF(AB6=1,INT(B6)*1440+Z6,"") -> 66666780 | AX6: =IF(AB6=1,AW6+AD6,"") -> 66667020 | AY6: =IF(AND(AB6=1,AV6=0,AU6=1),1,0) -> 1 | AZ6: =IF(AY6=1,COUNTIFS(R_Emp,D6,R_SAbs,"<"&AX6,R_EAbs,">"&AW6,R_OKey,1)-1,0) -> 0 | BA6: =IF(AY6=1,COUNTIFS(R_Emp,"<>"&D6,R_SAbs,"<"&AX6,R_EAbs,">"&AW6,R_OKey,1),0) -> 0 | BB6: =IF(AND(AB6=1,D6="proMX"),IF(AND(MOD(Z6,CFG_BLK)=0,MOD(AA6,CFG_BLK)=0,MOD(AG6,CFG_BLK)=0,AG6>0),1,0),1) -> 1 | BC6: =IF(Y6=0,"",IF(NOT(ISNUMBER(B6)),"Falta fecha o fecha inválida",IF(D6="","Falta empresa",IF(AND(D6<>"Malcolm",D6<>"proMX"),"Empresa inválida",IF(OR(INT(B6)<CFG_PSTART,INT(B6)>CFG_PEND),"Fecha fuera del período",IF(OR(NOT(ISNUMBER(Z6)),NOT(ISNUMBER(AA6))),"Falta hora inicio/fin o formato inválido",IF(AB6=0,"Hora inicio = hora fin",IF(AE6<0,"Descanso inválido",IF(AE6>=AD6,"Descanso ≥ duración",IF(AV6=1,"Registro duplicado",IF(AZ6>0,"Se superpone con otro registro "&D6,IF(BB6=0,"inicio, fin y duración neta deben ser múltiplos de "&CFG_BLK&" min","")))))))))))) | BD6: =IF(AND(Y6=1,BC6=""),1,0) -> 1 | BE6: =IF(AND(BD6=1,AU6=1),1,0) -> 1 | BF6: =IF(AND(D6="proMX",BD6=1),IF(R6="","Draft",R6),"") -> Approved | BG6: =IF(BD6=1,ROUND(AG6/60,6),0) -> 4 | BH6: =IF(BE6=1,ROUND(AG6/60,6),0) -> 4 | BI6: =IF(BE6=1,ROUND(AP6/60,6),0) -> 4 | BJ6: =IF(BE6=1,ROUND(AQ6/60,6),0) -> 0 | BK6: =IF(BE6=1,ROUND((AR6+AS6)/60,6),0) -> 4 | BL6: =ROUND(BH6-BK6,6) -> 0 | BM6: =IF(BE6=1,ROUND(AR6/60,6),0) -> 4 | BN6: =ROUND(BI6-BM6,6) -> 0 | BO6: =IF(BE6=1,ROUND(AS6/60,6),0) -> 0 | BP6: =ROUND(BJ6-BO6,6) -> 0 | BQ6: =IF(BE6=1,AW6,0) -> 66666780 | BR6: =IF(BE6=1,AX6,0) -> 66667020 | BS6: =IF(AND(BE6=1,D6="Malcolm",BA6>0),MIN(BH6,SUMPRODUCT((R_Emp="proMX")*(R_EN>0)*((R_EN-(R_EN>BR6)*(R_EN-BR6))>(R_SN+(R_SN<BQ6)*(BQ6-R_SN)))*((R_EN-(R_EN>BR6)*(R_EN-BR6))-(R_SN+(R_SN<BQ6)*(BQ6-R_SN))))/60),0) -> 0 | BT6: =IF(AND(BE6=1,D6="proMX"),ROUND(BI6*CFG_RATE+BJ6*CFG_OTRATE,6),0) -> 200 | BU6: =IF(AND(BD6=1,D6="proMX"),ROUND(AG6/CFG_BLK,6),0) -> 8 | BV6: =IF(BF6="Approved",IF(ISNUMBER(T6),INT(T6),INT(B6)),"") -> 46300 | BW6: =IF(ISNUMBER(B6),IF(DB_MON="Todos",1,IF(AND(INT(B6)>=DB_MS,INT(B6)<=DB_ME),1,0)),0) -> 1 | BX6: =IF(DB_PROJ="Todos",1,IF(E6&""=DB_PROJ&"",1,0)) -> 1 | BY6: =BW6*BX6 -> 1 | BZ6: =IF(Y6=1,F6&IF(AND(F6&""<>"",E6&""<>"")," · ","")&E6,"") -> PMX-203 · Portal Cliente | CA6: =IF(AND(BD6=1,E6&""<>""),IF(COUNTIFS($E$5:E5,E6,$BD$5:BD5,1)=0,MAX($CA$5:CA5)+1,""),"") -> 1 | CB6: =IF(AND(BE6=1,D6="Malcolm",E6&""<>""),IF(COUNTIFS($D$5:D5,"Malcolm",$E$5:E5,E6,$BE$5:BE5,1)=0,MAX($CB$5:CB5)+1,""),"") | CC6: =IF(AND(BD6=1,D6="proMX",E6&""<>""),IF(COUNTIFS($D$5:D5,"proMX",$E$5:E5,E6,$BD$5:BD5,1)=0,MAX($CC$5:CC5)+1,""),"") -> 1 | CD6: =IF(AND(BE6=1,D6="Malcolm",F6&""<>""),IF(COUNTIFS($D$5:D5,"Malcolm",$F$5:F5,F6,$BE$5:BE5,1)=0,MAX($CD$5:CD5)+1,""),"") | CE6: =IF(AND(BD6=1,D6="proMX",F6&""<>""),IF(COUNTIFS($D$5:D5,"proMX",$F$5:F5,F6,$BD$5:BD5,1)=0,MAX($CE$5:CE5)+1,""),"") -> 1 | CF6: =IF(AND(D6="proMX",BD6=1),IF(OR(BF6="Draft",BF6="Submitted",BF6="Returned",BF6="Recall Requested"),MAX($CF$5:CF5)+1,""),"") | CG6: =IF(BD6=0,0,IF(D6="Malcolm",1,MATCH(BF6,{"Draft","Submitted","Approved","Returned","Recall Requested","Cancelled"},0)+1)) -> 4 | CH6: =IF(AND(BF6="Submitted",ISNUMBER(V6)),IF(V6>CFG_MAXD,1,0),0) -> 0
A7: =IF(Y7=1,ROW()-5,"") -> 2 | B7: 46296 | C7: =IF(ISNUMBER(B7),CHOOSE(WEEKDAY(B7,2),"Lun","Mar","Mié","Jue","Vie","Sáb","Dom"),"") -> Jue | D7: proMX | E7: Portal Cliente | F7: PMX-204 | G7: [EJEMPLO] Testing | H7: 0.58333333 | I7: 0.66666667 | J7: 0 | K7: =IF(AB7=1,ROUND(AG7/60,4),"") -> 2 | L7: =IF(BD7=1,ROUND(AP7/60,4),"") -> 2 | M7: =IF(BD7=1,ROUND(AQ7/60,4),"") -> 0 | N7: =IF(AND(D7="proMX",AB7=1),ROUND(AG7/CFG_BLK,2),"") -> 4 | O7: =IF(D7="proMX",IF(BD7=1,ROUND(AG7/60,4),0),"") -> 2 | P7: =IF(Y7=0,"",IF(BD7=1,"OK",IF(D7="proMX","Revisar bloques: ","Revisar: ")&BC7)) -> OK | Q7: =IF(NOT(ISNUMBER(B7)),"",IF(COUNTIFS(FER_F,INT(B7))>0,"Feriado"&IF(AH7=1," (laborable)"," (no laborable)"),IF(AH7=1,"Laborable",IF(WEEKDAY(B7,2)>5,"Fin de semana","No laborable")))) -> Laborable | R7: Approved | S7: 46297 | T7: 46300 | U7: EJEMPLO – se puede borrar | V7: =IF(AND(D7="proMX",OR(R7="Submitted",R7="Recall Requested"),ISNUMBER(S7)),CFG_TODAY-INT(S7),"") | W7: =IF(BD7=0,"",IF(BA7>0,"⚠ Se superpone con un registro de la otra empresa",IF(D7="Malcolm",IF(COUNTA(R7,S7,T7)>0,"Estado/fechas proMX se ignoran en Malcolm",""),IF(BF7="Cancelled","Cancelado: excluido de totales",IF(R7="","Sin estado: se trata como Draft",IF(BF7="Submitted",IF(ISNUMBER(V7),IF(V7>CFG_MAXD,"⚠ "&V7&" días en Submitted (máx. "&CFG_MAXD&")",""),"Falta fecha de envío"),IF(BF7="Returned","⚠ Devuelto: corregir y reenviar",IF(BF7="Recall Requested","Retirada solicitada: pendiente",IF(AND(BF7="Approved",NOT(ISNUMBER(T7))),"Falta fecha de aprobación",IF(AND(ISNUMBER(S7),ISNUMBER(T7),T7<S7),"Aprobación anterior al envío",""))))))))) | Y7: =IF(COUNTA(B7,D7,E7,F7,G7,H7,I7,J7,R7,S7,T7)>0,1,0) -> 1 | Z7: =IF(AND(ISNUMBER(H7),H7>=0,H7<1),ROUND(H7*1440,0),"") -> 840 | AA7: =IF(AND(ISNUMBER(I7),I7>=0,I7<1),ROUND(I7*1440,0),"") -> 960 | AB7: =IF(AND(ISNUMBER(B7),D7<>"",ISNUMBER(Z7),ISNUMBER(AA7)),IF(Z7=AA7,0,1),0) -> 1 | AC7: =IF(AB7=1,IF(AA7<Z7,1,0),0) -> 0 | AD7: =IF(AB7=1,IF(AC7=1,1440-Z7+AA7,AA7-Z7),0) -> 120 | AE7: =IF(J7="",0,IF(ISNUMBER(J7),J7,-1)) -> 0 | AF7: =MIN(MAX(0,AE7),AD7) -> 0 | AG7: =MAX(0,AD7-MAX(0,AE7)) -> 120 | AH7: =IF(ISNUMBER(B7),IF(AND(INDEX(CFG_WDAYS,WEEKDAY(INT(B7),2))="Sí",IF(D7="proMX",COUNTIFS(FER_F,INT(B7),FER_NLP,"Sí"),COUNTIFS(FER_F,INT(B7),FER_NLM,"Sí"))=0),1,0),0) -> 1 | AI7: =IF(AC7=1,IF(AND(INDEX(CFG_WDAYS,WEEKDAY(INT(B7)+1,2))="Sí",IF(D7="proMX",COUNTIFS(FER_F,INT(B7)+1,FER_NLP,"Sí"),COUNTIFS(FER_F,INT(B7)+1,FER_NLM,"Sí"))=0),1,0),0) -> 0 | AJ7: =IF(AC7=1,1440-Z7,AD7) -> 120 | AK7: =IF(AND(AB7=1,AH7=1),MAX(0,MIN(IF(AC7=1,1440,AA7),CFG_WEM)-MAX(Z7,CFG_WSM)),0) -> 120 | AL7: =IF(AND(AC7=1,AI7=1),MAX(0,MIN(AA7,CFG_WEM)-CFG_WSM),0) -> 0 | AM7: =AK7+AL7 -> 120 | AN7: =IF(CFG_BRK="Proporcional",IF(AD7=0,0,AF7*AM7/AD7),IF(CFG_BRK="Extras primero",MIN(AM7,MAX(0,AF7-(AD7-AM7))),MIN(AF7,AM7))) -> 0 | AO7: =AF7-AN7 -> 0 | AP7: =AM7-AN7 -> 120 | AQ7: =AD7-AM7-AO7 -> 0 | AR7: =IF(AM7=0,0,AK7-AN7*AK7/AM7) -> 120 | AS7: =IF(AD7-AM7=0,0,(AJ7-AK7)-AO7*(AJ7-AK7)/(AD7-AM7)) -> 0 | AT7: =IF(AC7=1,INT(B7)+1,"") | AU7: =IF(AND(D7="proMX",R7="Cancelled"),0,1) -> 1 | AV7: =IF(AND(AB7=1,AU7=1),IF(COUNTIFS($D$5:D6,D7,$B$5:B6,B7,$Z$5:Z6,Z7,$AA$5:AA6,AA7,$F$5:F6,F7&"",$AU$5:AU6,1)>0,1,0),0) -> 0 | AW7: =IF(AB7=1,INT(B7)*1440+Z7,"") -> 66667080 | AX7: =IF(AB7=1,AW7+AD7,"") -> 66667200 | AY7: =IF(AND(AB7=1,AV7=0,AU7=1),1,0) -> 1 | AZ7: =IF(AY7=1,COUNTIFS(R_Emp,D7,R_SAbs,"<"&AX7,R_EAbs,">"&AW7,R_OKey,1)-1,0) -> 0 | BA7: =IF(AY7=1,COUNTIFS(R_Emp,"<>"&D7,R_SAbs,"<"&AX7,R_EAbs,">"&AW7,R_OKey,1),0) -> 0 | BB7: =IF(AND(AB7=1,D7="proMX"),IF(AND(MOD(Z7,CFG_BLK)=0,MOD(AA7,CFG_BLK)=0,MOD(AG7,CFG_BLK)=0,AG7>0),1,0),1) -> 1 | BC7: =IF(Y7=0,"",IF(NOT(ISNUMBER(B7)),"Falta fecha o fecha inválida",IF(D7="","Falta empresa",IF(AND(D7<>"Malcolm",D7<>"proMX"),"Empresa inválida",IF(OR(INT(B7)<CFG_PSTART,INT(B7)>CFG_PEND),"Fecha fuera del período",IF(OR(NOT(ISNUMBER(Z7)),NOT(ISNUMBER(AA7))),"Falta hora inicio/fin o formato inválido",IF(AB7=0,"Hora inicio = hora fin",IF(AE7<0,"Descanso inválido",IF(AE7>=AD7,"Descanso ≥ duración",IF(AV7=1,"Registro duplicado",IF(AZ7>0,"Se superpone con otro registro "&D7,IF(BB7=0,"inicio, fin y duración neta deben ser múltiplos de "&CFG_BLK&" min","")))))))))))) | BD7: =IF(AND(Y7=1,BC7=""),1,0) -> 1 | BE7: =IF(AND(BD7=1,AU7=1),1,0) -> 1 | BF7: =IF(AND(D7="proMX",BD7=1),IF(R7="","Draft",R7),"") -> Approved | BG7: =IF(BD7=1,ROUND(AG7/60,6),0) -> 2 | BH7: =IF(BE7=1,ROUND(AG7/60,6),0) -> 2 | BI7: =IF(BE7=1,ROUND(AP7/60,6),0) -> 2 | BJ7: =IF(BE7=1,ROUND(AQ7/60,6),0) -> 0 | BK7: =IF(BE7=1,ROUND((AR7+AS7)/60,6),0) -> 2 | BL7: =ROUND(BH7-BK7,6) -> 0 | BM7: =IF(BE7=1,ROUND(AR7/60,6),0) -> 2 | BN7: =ROUND(BI7-BM7,6) -> 0 | BO7: =IF(BE7=1,ROUND(AS7/60,6),0) -> 0 | BP7: =ROUND(BJ7-BO7,6) -> 0 | BQ7: =IF(BE7=1,AW7,0) -> 66667080 | BR7: =IF(BE7=1,AX7,0) -> 66667200 | BS7: =IF(AND(BE7=1,D7="Malcolm",BA7>0),MIN(BH7,SUMPRODUCT((R_Emp="proMX")*(R_EN>0)*((R_EN-(R_EN>BR7)*(R_EN-BR7))>(R_SN+(R_SN<BQ7)*(BQ7-R_SN)))*((R_EN-(R_EN>BR7)*(R_EN-BR7))-(R_SN+(R_SN<BQ7)*(BQ7-R_SN))))/60),0) -> 0 | BT7: =IF(AND(BE7=1,D7="proMX"),ROUND(BI7*CFG_RATE+BJ7*CFG_OTRATE,6),0) -> 100 | BU7: =IF(AND(BD7=1,D7="proMX"),ROUND(AG7/CFG_BLK,6),0) -> 4 | BV7: =IF(BF7="Approved",IF(ISNUMBER(T7),INT(T7),INT(B7)),"") -> 46300 | BW7: =IF(ISNUMBER(B7),IF(DB_MON="Todos",1,IF(AND(INT(B7)>=DB_MS,INT(B7)<=DB_ME),1,0)),0) -> 1 | BX7: =IF(DB_PROJ="Todos",1,IF(E7&""=DB_PROJ&"",1,0)) -> 1 | BY7: =BW7*BX7 -> 1 | BZ7: =IF(Y7=1,F7&IF(AND(F7&""<>"",E7&""<>"")," · ","")&E7,"") -> PMX-204 · Portal Cliente | CA7: =IF(AND(BD7=1,E7&""<>""),IF(COUNTIFS($E$5:E6,E7,$BD$5:BD6,1)=0,MAX($CA$5:CA6)+1,""),"") | CB7: =IF(AND(BE7=1,D7="Malcolm",E7&""<>""),IF(COUNTIFS($D$5:D6,"Malcolm",$E$5:E6,E7,$BE$5:BE6,1)=0,MAX($CB$5:CB6)+1,""),"") | CC7: =IF(AND(BD7=1,D7="proMX",E7&""<>""),IF(COUNTIFS($D$5:D6,"proMX",$E$5:E6,E7,$BD$5:BD6,1)=0,MAX($CC$5:CC6)+1,""),"") | CD7: =IF(AND(BE7=1,D7="Malcolm",F7&""<>""),IF(COUNTIFS($D$5:D6,"Malcolm",$F$5:F6,F7,$BE$5:BE6,1)=0,MAX($CD$5:CD6)+1,""),"") | CE7: =IF(AND(BD7=1,D7="proMX",F7&""<>""),IF(COUNTIFS($D$5:D6,"proMX",$F$5:F6,F7,$BD$5:BD6,1)=0,MAX($CE$5:CE6)+1,""),"") -> 2 | CF7: =IF(AND(D7="proMX",BD7=1),IF(OR(BF7="Draft",BF7="Submitted",BF7="Returned",BF7="Recall Requested"),MAX($CF$5:CF6)+1,""),"") | CG7: =IF(BD7=0,0,IF(D7="Malcolm",1,MATCH(BF7,{"Draft","Submitted","Approved","Returned","Recall Requested","Cancelled"},0)+1)) -> 4 | CH7: =IF(AND(BF7="Submitted",ISNUMBER(V7)),IF(V7>CFG_MAXD,1,0),0) -> 0
A8: =IF(Y8=1,ROW()-5,"") -> 3 | B8: 46297 | C8: =IF(ISNUMBER(B8),CHOOSE(WEEKDAY(B8,2),"Lun","Mar","Mié","Jue","Vie","Sáb","Dom"),"") -> Vie | D8: proMX | E8: Portal Cliente | F8: PMX-202 | G8: [EJEMPLO] Implementación | H8: 0.375 | I8: 0.5 | J8: 0 | K8: =IF(AB8=1,ROUND(AG8/60,4),"") -> 3 | L8: =IF(BD8=1,ROUND(AP8/60,4),"") -> 3 | M8: =IF(BD8=1,ROUND(AQ8/60,4),"") -> 0 | N8: =IF(AND(D8="proMX",AB8=1),ROUND(AG8/CFG_BLK,2),"") -> 6 | O8: =IF(D8="proMX",IF(BD8=1,ROUND(AG8/60,4),0),"") -> 3 | P8: =IF(Y8=0,"",IF(BD8=1,"OK",IF(D8="proMX","Revisar bloques: ","Revisar: ")&BC8)) -> OK | Q8: =IF(NOT(ISNUMBER(B8)),"",IF(COUNTIFS(FER_F,INT(B8))>0,"Feriado"&IF(AH8=1," (laborable)"," (no laborable)"),IF(AH8=1,"Laborable",IF(WEEKDAY(B8,2)>5,"Fin de semana","No laborable")))) -> Laborable | R8: Submitted | S8: 46297 | U8: EJEMPLO – se puede borrar | V8: =IF(AND(D8="proMX",OR(R8="Submitted",R8="Recall Requested"),ISNUMBER(S8)),CFG_TODAY-INT(S8),"") -> 11 | W8: =IF(BD8=0,"",IF(BA8>0,"⚠ Se superpone con un registro de la otra empresa",IF(D8="Malcolm",IF(COUNTA(R8,S8,T8)>0,"Estado/fechas proMX se ignoran en Malcolm",""),IF(BF8="Cancelled","Cancelado: excluido de totales",IF(R8="","Sin estado: se trata como Draft",IF(BF8="Submitted",IF(ISNUMBER(V8),IF(V8>CFG_MAXD,"⚠ "&V8&" días en Submitted (máx. "&CFG_MAXD&")",""),"Falta fecha de envío"),IF(BF8="Returned","⚠ Devuelto: corregir y reenviar",IF(BF8="Recall Requested","Retirada solicitada: pendiente",IF(AND(BF8="Approved",NOT(ISNUMBER(T8))),"Falta fecha de aprobación",IF(AND(ISNUMBER(S8),ISNUMBER(T8),T8<S8),"Aprobación anterior al envío",""))))))))) -> ⚠ 11 días en Submitted (máx. 7) | Y8: =IF(COUNTA(B8,D8,E8,F8,G8,H8,I8,J8,R8,S8,T8)>0,1,0) -> 1 | Z8: =IF(AND(ISNUMBER(H8),H8>=0,H8<1),ROUND(H8*1440,0),"") -> 540 | AA8: =IF(AND(ISNUMBER(I8),I8>=0,I8<1),ROUND(I8*1440,0),"") -> 720 | AB8: =IF(AND(ISNUMBER(B8),D8<>"",ISNUMBER(Z8),ISNUMBER(AA8)),IF(Z8=AA8,0,1),0) -> 1 | AC8: =IF(AB8=1,IF(AA8<Z8,1,0),0) -> 0 | AD8: =IF(AB8=1,IF(AC8=1,1440-Z8+AA8,AA8-Z8),0) -> 180 | AE8: =IF(J8="",0,IF(ISNUMBER(J8),J8,-1)) -> 0 | AF8: =MIN(MAX(0,AE8),AD8) -> 0 | AG8: =MAX(0,AD8-MAX(0,AE8)) -> 180 | AH8: =IF(ISNUMBER(B8),IF(AND(INDEX(CFG_WDAYS,WEEKDAY(INT(B8),2))="Sí",IF(D8="proMX",COUNTIFS(FER_F,INT(B8),FER_NLP,"Sí"),COUNTIFS(FER_F,INT(B8),FER_NLM,"Sí"))=0),1,0),0) -> 1 | AI8: =IF(AC8=1,IF(AND(INDEX(CFG_WDAYS,WEEKDAY(INT(B8)+1,2))="Sí",IF(D8="proMX",COUNTIFS(FER_F,INT(B8)+1,FER_NLP,"Sí"),COUNTIFS(FER_F,INT(B8)+1,FER_NLM,"Sí"))=0),1,0),0) -> 0 | AJ8: =IF(AC8=1,1440-Z8,AD8) -> 180 | AK8: =IF(AND(AB8=1,AH8=1),MAX(0,MIN(IF(AC8=1,1440,AA8),CFG_WEM)-MAX(Z8,CFG_WSM)),0) -> 180 | AL8: =IF(AND(AC8=1,AI8=1),MAX(0,MIN(AA8,CFG_WEM)-CFG_WSM),0) -> 0 | AM8: =AK8+AL8 -> 180 | AN8: =IF(CFG_BRK="Proporcional",IF(AD8=0,0,AF8*AM8/AD8),IF(CFG_BRK="Extras primero",MIN(AM8,MAX(0,AF8-(AD8-AM8))),MIN(AF8,AM8))) -> 0 | AO8: =AF8-AN8 -> 0 | AP8: =AM8-AN8 -> 180 | AQ8: =AD8-AM8-AO8 -> 0 | AR8: =IF(AM8=0,0,AK8-AN8*AK8/AM8) -> 180 | AS8: =IF(AD8-AM8=0,0,(AJ8-AK8)-AO8*(AJ8-AK8)/(AD8-AM8)) -> 0 | AT8: =IF(AC8=1,INT(B8)+1,"") | AU8: =IF(AND(D8="proMX",R8="Cancelled"),0,1) -> 1 | AV8: =IF(AND(AB8=1,AU8=1),IF(COUNTIFS($D$5:D7,D8,$B$5:B7,B8,$Z$5:Z7,Z8,$AA$5:AA7,AA8,$F$5:F7,F8&"",$AU$5:AU7,1)>0,1,0),0) -> 0 | AW8: =IF(AB8=1,INT(B8)*1440+Z8,"") -> 66668220 | AX8: =IF(AB8=1,AW8+AD8,"") -> 66668400 | AY8: =IF(AND(AB8=1,AV8=0,AU8=1),1,0) -> 1 | AZ8: =IF(AY8=1,COUNTIFS(R_Emp,D8,R_SAbs,"<"&AX8,R_EAbs,">"&AW8,R_OKey,1)-1,0) -> 0 | BA8: =IF(AY8=1,COUNTIFS(R_Emp,"<>"&D8,R_SAbs,"<"&AX8,R_EAbs,">"&AW8,R_OKey,1),0) -> 0 | BB8: =IF(AND(AB8=1,D8="proMX"),IF(AND(MOD(Z8,CFG_BLK)=0,MOD(AA8,CFG_BLK)=0,MOD(AG8,CFG_BLK)=0,AG8>0),1,0),1) -> 1 | BC8: =IF(Y8=0,"",IF(NOT(ISNUMBER(B8)),"Falta fecha o fecha inválida",IF(D8="","Falta empresa",IF(AND(D8<>"Malcolm",D8<>"proMX"),"Empresa inválida",IF(OR(INT(B8)<CFG_PSTART,INT(B8)>CFG_PEND),"Fecha fuera del período",IF(OR(NOT(ISNUMBER(Z8)),NOT(ISNUMBER(AA8))),"Falta hora inicio/fin o formato inválido",IF(AB8=0,"Hora inicio = hora fin",IF(AE8<0,"Descanso inválido",IF(AE8>=AD8,"Descanso ≥ duración",IF(AV8=1,"Registro duplicado",IF(AZ8>0,"Se superpone con otro registro "&D8,IF(BB8=0,"inicio, fin y duración neta deben ser múltiplos de "&CFG_BLK&" min","")))))))))))) | BD8: =IF(AND(Y8=1,BC8=""),1,0) -> 1 | BE8: =IF(AND(BD8=1,AU8=1),1,0) -> 1 | BF8: =IF(AND(D8="proMX",BD8=1),IF(R8="","Draft",R8),"") -> Submitted | BG8: =IF(BD8=1,ROUND(AG8/60,6),0) -> 3 | BH8: =IF(BE8=1,ROUND(AG8/60,6),0) -> 3 | BI8: =IF(BE8=1,ROUND(AP8/60,6),0) -> 3 | BJ8: =IF(BE8=1,ROUND(AQ8/60,6),0) -> 0 | BK8: =IF(BE8=1,ROUND((AR8+AS8)/60,6),0) -> 3 | BL8: =ROUND(BH8-BK8,6) -> 0 | BM8: =IF(BE8=1,ROUND(AR8/60,6),0) -> 3 | BN8: =ROUND(BI8-BM8,6) -> 0 | BO8: =IF(BE8=1,ROUND(AS8/60,6),0) -> 0 | BP8: =ROUND(BJ8-BO8,6) -> 0 | BQ8: =IF(BE8=1,AW8,0) -> 66668220 | BR8: =IF(BE8=1,AX8,0) -> 66668400 | BS8: =IF(AND(BE8=1,D8="Malcolm",BA8>0),MIN(BH8,SUMPRODUCT((R_Emp="proMX")*(R_EN>0)*((R_EN-(R_EN>BR8)*(R_EN-BR8))>(R_SN+(R_SN<BQ8)*(BQ8-R_SN)))*((R_EN-(R_EN>BR8)*(R_EN-BR8))-(R_SN+(R_SN<BQ8)*(BQ8-R_SN))))/60),0) -> 0 | BT8: =IF(AND(BE8=1,D8="proMX"),ROUND(BI8*CFG_RATE+BJ8*CFG_OTRATE,6),0) -> 150 | BU8: =IF(AND(BD8=1,D8="proMX"),ROUND(AG8/CFG_BLK,6),0) -> 6 | BV8: =IF(BF8="Approved",IF(ISNUMBER(T8),INT(T8),INT(B8)),"") | BW8: =IF(ISNUMBER(B8),IF(DB_MON="Todos",1,IF(AND(INT(B8)>=DB_MS,INT(B8)<=DB_ME),1,0)),0) -> 1 | BX8: =IF(DB_PROJ="Todos",1,IF(E8&""=DB_PROJ&"",1,0)) -> 1 | BY8: =BW8*BX8 -> 1 | BZ8: =IF(Y8=1,F8&IF(AND(F8&""<>"",E8&""<>"")," · ","")&E8,"") -> PMX-202 · Portal Cliente | CA8: =IF(AND(BD8=1,E8&""<>""),IF(COUNTIFS($E$5:E7,E8,$BD$5:BD7,1)=0,MAX($CA$5:CA7)+1,""),"") | CB8: =IF(AND(BE8=1,D8="Malcolm",E8&""<>""),IF(COUNTIFS($D$5:D7,"Malcolm",$E$5:E7,E8,$BE$5:BE7,1)=0,MAX($CB$5:CB7)+1,""),"") | CC8: =IF(AND(BD8=1,D8="proMX",E8&""<>""),IF(COUNTIFS($D$5:D7,"proMX",$E$5:E7,E8,$BD$5:BD7,1)=0,MAX($CC$5:CC7)+1,""),"") | CD8: =IF(AND(BE8=1,D8="Malcolm",F8&""<>""),IF(COUNTIFS($D$5:D7,"Malcolm",$F$5:F7,F8,$BE$5:BE7,1)=0,MAX($CD$5:CD7)+1,""),"") | CE8: =IF(AND(BD8=1,D8="proMX",F8&""<>""),IF(COUNTIFS($D$5:D7,"proMX",$F$5:F7,F8,$BD$5:BD7,1)=0,MAX($CE$5:CE7)+1,""),"") -> 3 | CF8: =IF(AND(D8="proMX",BD8=1),IF(OR(BF8="Draft",BF8="Submitted",BF8="Returned",BF8="Recall Requested"),MAX($CF$5:CF7)+1,""),"") -> 1 | CG8: =IF(BD8=0,0,IF(D8="Malcolm",1,MATCH(BF8,{"Draft","Submitted","Approved","Returned","Recall Requested","Cancelled"},0)+1)) -> 3 | CH8: =IF(AND(BF8="Submitted",ISNUMBER(V8)),IF(V8>CFG_MAXD,1,0),0) -> 1
A9: =IF(Y9=1,ROW()-5,"") -> 4 | B9: 46300 | C9: =IF(ISNUMBER(B9),CHOOSE(WEEKDAY(B9,2),"Lun","Mar","Mié","Jue","Vie","Sáb","Dom"),"") -> Lun | D9: Malcolm | E9: PCF | F9: PCF-101 | G9: [EJEMPLO] Desarrollo PCF | H9: 0.375 | I9: 0.5 | J9: 0 | K9: =IF(AB9=1,ROUND(AG9/60,4),"") -> 3 | L9: =IF(BD9=1,ROUND(AP9/60,4),"") -> 3 | M9: =IF(BD9=1,ROUND(AQ9/60,4),"") -> 0 | N9: =IF(AND(D9="proMX",AB9=1),ROUND(AG9/CFG_BLK,2),"") | O9: =IF(D9="proMX",IF(BD9=1,ROUND(AG9/60,4),0),"") | P9: =IF(Y9=0,"",IF(BD9=1,"OK",IF(D9="proMX","Revisar bloques: ","Revisar: ")&BC9)) -> OK | Q9: =IF(NOT(ISNUMBER(B9)),"",IF(COUNTIFS(FER_F,INT(B9))>0,"Feriado"&IF(AH9=1," (laborable)"," (no laborable)"),IF(AH9=1,"Laborable",IF(WEEKDAY(B9,2)>5,"Fin de semana","No laborable")))) -> Laborable | U9: EJEMPLO – se puede borrar | V9: =IF(AND(D9="proMX",OR(R9="Submitted",R9="Recall Requested"),ISNUMBER(S9)),CFG_TODAY-INT(S9),"") | W9: =IF(BD9=0,"",IF(BA9>0,"⚠ Se superpone con un registro de la otra empresa",IF(D9="Malcolm",IF(COUNTA(R9,S9,T9)>0,"Estado/fechas proMX se ignoran en Malcolm",""),IF(BF9="Cancelled","Cancelado: excluido de totales",IF(R9="","Sin estado: se trata como Draft",IF(BF9="Submitted",IF(ISNUMBER(V9),IF(V9>CFG_MAXD,"⚠ "&V9&" días en Submitted (máx. "&CFG_MAXD&")",""),"Falta fecha de envío"),IF(BF9="Returned","⚠ Devuelto: corregir y reenviar",IF(BF9="Recall Requested","Retirada solicitada: pendiente",IF(AND(BF9="Approved",NOT(ISNUMBER(T9))),"Falta fecha de aprobación",IF(AND(ISNUMBER(S9),ISNUMBER(T9),T9<S9),"Aprobación anterior al envío",""))))))))) | Y9: =IF(COUNTA(B9,D9,E9,F9,G9,H9,I9,J9,R9,S9,T9)>0,1,0) -> 1 | Z9: =IF(AND(ISNUMBER(H9),H9>=0,H9<1),ROUND(H9*1440,0),"") -> 540 | AA9: =IF(AND(ISNUMBER(I9),I9>=0,I9<1),ROUND(I9*1440,0),"") -> 720 | AB9: =IF(AND(ISNUMBER(B9),D9<>"",ISNUMBER(Z9),ISNUMBER(AA9)),IF(Z9=AA9,0,1),0) -> 1 | AC9: =IF(AB9=1,IF(AA9<Z9,1,0),0) -> 0 | AD9: =IF(AB9=1,IF(AC9=1,1440-Z9+AA9,AA9-Z9),0) -> 180 | AE9: =IF(J9="",0,IF(ISNUMBER(J9),J9,-1)) -> 0 | AF9: =MIN(MAX(0,AE9),AD9) -> 0 | AG9: =MAX(0,AD9-MAX(0,AE9)) -> 180 | AH9: =IF(ISNUMBER(B9),IF(AND(INDEX(CFG_WDAYS,WEEKDAY(INT(B9),2))="Sí",IF(D9="proMX",COUNTIFS(FER_F,INT(B9),FER_NLP,"Sí"),COUNTIFS(FER_F,INT(B9),FER_NLM,"Sí"))=0),1,0),0) -> 1 | AI9: =IF(AC9=1,IF(AND(INDEX(CFG_WDAYS,WEEKDAY(INT(B9)+1,2))="Sí",IF(D9="proMX",COUNTIFS(FER_F,INT(B9)+1,FER_NLP,"Sí"),COUNTIFS(FER_F,INT(B9)+1,FER_NLM,"Sí"))=0),1,0),0) -> 0 | AJ9: =IF(AC9=1,1440-Z9,AD9) -> 180 | AK9: =IF(AND(AB9=1,AH9=1),MAX(0,MIN(IF(AC9=1,1440,AA9),CFG_WEM)-MAX(Z9,CFG_WSM)),0) -> 180 | AL9: =IF(AND(AC9=1,AI9=1),MAX(0,MIN(AA9,CFG_WEM)-CFG_WSM),0) -> 0 | AM9: =AK9+AL9 -> 180 | AN9: =IF(CFG_BRK="Proporcional",IF(AD9=0,0,AF9*AM9/AD9),IF(CFG_BRK="Extras primero",MIN(AM9,MAX(0,AF9-(AD9-AM9))),MIN(AF9,AM9))) -> 0 | AO9: =AF9-AN9 -> 0 | AP9: =AM9-AN9 -> 180 | AQ9: =AD9-AM9-AO9 -> 0 | AR9: =IF(AM9=0,0,AK9-AN9*AK9/AM9) -> 180 | AS9: =IF(AD9-AM9=0,0,(AJ9-AK9)-AO9*(AJ9-AK9)/(AD9-AM9)) -> 0 | AT9: =IF(AC9=1,INT(B9)+1,"") | AU9: =IF(AND(D9="proMX",R9="Cancelled"),0,1) -> 1 | AV9: =IF(AND(AB9=1,AU9=1),IF(COUNTIFS($D$5:D8,D9,$B$5:B8,B9,$Z$5:Z8,Z9,$AA$5:AA8,AA9,$F$5:F8,F9&"",$AU$5:AU8,1)>0,1,0),0) -> 0 | AW9: =IF(AB9=1,INT(B9)*1440+Z9,"") -> 66672540 | AX9: =IF(AB9=1,AW9+AD9,"") -> 66672720 | AY9: =IF(AND(AB9=1,AV9=0,AU9=1),1,0) -> 1 | AZ9: =IF(AY9=1,COUNTIFS(R_Emp,D9,R_SAbs,"<"&AX9,R_EAbs,">"&AW9,R_OKey,1)-1,0) -> 0 | BA9: =IF(AY9=1,COUNTIFS(R_Emp,"<>"&D9,R_SAbs,"<"&AX9,R_EAbs,">"&AW9,R_OKey,1),0) -> 0 | BB9: =IF(AND(AB9=1,D9="proMX"),IF(AND(MOD(Z9,CFG_BLK)=0,MOD(AA9,CFG_BLK)=0,MOD(AG9,CFG_BLK)=0,AG9>0),1,0),1) -> 1 | BC9: =IF(Y9=0,"",IF(NOT(ISNUMBER(B9)),"Falta fecha o fecha inválida",IF(D9="","Falta empresa",IF(AND(D9<>"Malcolm",D9<>"proMX"),"Empresa inválida",IF(OR(INT(B9)<CFG_PSTART,INT(B9)>CFG_PEND),"Fecha fuera del período",IF(OR(NOT(ISNUMBER(Z9)),NOT(ISNUMBER(AA9))),"Falta hora inicio/fin o formato inválido",IF(AB9=0,"Hora inicio = hora fin",IF(AE9<0,"Descanso inválido",IF(AE9>=AD9,"Descanso ≥ duración",IF(AV9=1,"Registro duplicado",IF(AZ9>0,"Se superpone con otro registro "&D9,IF(BB9=0,"inicio, fin y duración neta deben ser múltiplos de "&CFG_BLK&" min","")))))))))))) | BD9: =IF(AND(Y9=1,BC9=""),1,0) -> 1 | BE9: =IF(AND(BD9=1,AU9=1),1,0) -> 1 | BF9: =IF(AND(D9="proMX",BD9=1),IF(R9="","Draft",R9),"") | BG9: =IF(BD9=1,ROUND(AG9/60,6),0) -> 3 | BH9: =IF(BE9=1,ROUND(AG9/60,6),0) -> 3 | BI9: =IF(BE9=1,ROUND(AP9/60,6),0) -> 3 | BJ9: =IF(BE9=1,ROUND(AQ9/60,6),0) -> 0 | BK9: =IF(BE9=1,ROUND((AR9+AS9)/60,6),0) -> 3 | BL9: =ROUND(BH9-BK9,6) -> 0 | BM9: =IF(BE9=1,ROUND(AR9/60,6),0) -> 3 | BN9: =ROUND(BI9-BM9,6) -> 0 | BO9: =IF(BE9=1,ROUND(AS9/60,6),0) -> 0 | BP9: =ROUND(BJ9-BO9,6) -> 0 | BQ9: =IF(BE9=1,AW9,0) -> 66672540 | BR9: =IF(BE9=1,AX9,0) -> 66672720 | BS9: =IF(AND(BE9=1,D9="Malcolm",BA9>0),MIN(BH9,SUMPRODUCT((R_Emp="proMX")*(R_EN>0)*((R_EN-(R_EN>BR9)*(R_EN-BR9))>(R_SN+(R_SN<BQ9)*(BQ9-R_SN)))*((R_EN-(R_EN>BR9)*(R_EN-BR9))-(R_SN+(R_SN<BQ9)*(BQ9-R_SN))))/60),0) -> 0 | BT9: =IF(AND(BE9=1,D9="proMX"),ROUND(BI9*CFG_RATE+BJ9*CFG_OTRATE,6),0) -> 0 | BU9: =IF(AND(BD9=1,D9="proMX"),ROUND(AG9/CFG_BLK,6),0) -> 0 | BV9: =IF(BF9="Approved",IF(ISNUMBER(T9),INT(T9),INT(B9)),"") | BW9: =IF(ISNUMBER(B9),IF(DB_MON="Todos",1,IF(AND(INT(B9)>=DB_MS,INT(B9)<=DB_ME),1,0)),0) -> 1 | BX9: =IF(DB_PROJ="Todos",1,IF(E9&""=DB_PROJ&"",1,0)) -> 1 | BY9: =BW9*BX9 -> 1 | BZ9: =IF(Y9=1,F9&IF(AND(F9&""<>"",E9&""<>"")," · ","")&E9,"") -> PCF-101 · PCF | CA9: =IF(AND(BD9=1,E9&""<>""),IF(COUNTIFS($E$5:E8,E9,$BD$5:BD8,1)=0,MAX($CA$5:CA8)+1,""),"") -> 2 | CB9: =IF(AND(BE9=1,D9="Malcolm",E9&""<>""),IF(COUNTIFS($D$5:D8,"Malcolm",$E$5:E8,E9,$BE$5:BE8,1)=0,MAX($CB$5:CB8)+1,""),"") -> 1 | CC9: =IF(AND(BD9=1,D9="proMX",E9&""<>""),IF(COUNTIFS($D$5:D8,"proMX",$E$5:E8,E9,$BD$5:BD8,1)=0,MAX($CC$5:CC8)+1,""),"") | CD9: =IF(AND(BE9=1,D9="Malcolm",F9&""<>""),IF(COUNTIFS($D$5:D8,"Malcolm",$F$5:F8,F9,$BE$5:BE8,1)=0,MAX($CD$5:CD8)+1,""),"") -> 1 | CE9: =IF(AND(BD9=1,D9="proMX",F9&""<>""),IF(COUNTIFS($D$5:D8,"proMX",$F$5:F8,F9,$BD$5:BD8,1)=0,MAX($CE$5:CE8)+1,""),"") | CF9: =IF(AND(D9="proMX",BD9=1),IF(OR(BF9="Draft",BF9="Submitted",BF9="Returned",BF9="Recall Requested"),MAX($CF$5:CF8)+1,""),"") | CG9: =IF(BD9=0,0,IF(D9="Malcolm",1,MATCH(BF9,{"Draft","Submitted","Approved","Returned","Recall Requested","Cancelled"},0)+1)) -> 1 | CH9: =IF(AND(BF9="Submitted",ISNUMBER(V9)),IF(V9>CFG_MAXD,1,0),0) -> 0
A10: =IF(Y10=1,ROW()-5,"") -> 5 | B10: 46300 | C10: =IF(ISNUMBER(B10),CHOOSE(WEEKDAY(B10,2),"Lun","Mar","Mié","Jue","Vie","Sáb","Dom"),"") -> Lun | D10: Malcolm | E10: PCF | F10: PCF-102 | G10: [EJEMPLO] Debugging | H10: 0.54166667 | I10: 0.59722222 | J10: 0 | K10: =IF(AB10=1,ROUND(AG10/60,4),"") -> 1.3333 | L10: =IF(BD10=1,ROUND(AP10/60,4),"") -> 1.3333 | M10: =IF(BD10=1,ROUND(AQ10/60,4),"") -> 0 | N10: =IF(AND(D10="proMX",AB10=1),ROUND(AG10/CFG_BLK,2),"") | O10: =IF(D10="proMX",IF(BD10=1,ROUND(AG10/60,4),0),"") | P10: =IF(Y10=0,"",IF(BD10=1,"OK",IF(D10="proMX","Revisar bloques: ","Revisar: ")&BC10)) -> OK | Q10: =IF(NOT(ISNUMBER(B10)),"",IF(COUNTIFS(FER_F,INT(B10))>0,"Feriado"&IF(AH10=1," (laborable)"," (no laborable)"),IF(AH10=1,"Laborable",IF(WEEKDAY(B10,2)>5,"Fin de semana","No laborable")))) -> Laborable | U10: EJEMPLO – se puede borrar | V10: =IF(AND(D10="proMX",OR(R10="Submitted",R10="Recall Requested"),ISNUMBER(S10)),CFG_TODAY-INT(S10),"") | W10: =IF(BD10=0,"",IF(BA10>0,"⚠ Se superpone con un registro de la otra empresa",IF(D10="Malcolm",IF(COUNTA(R10,S10,T10)>0,"Estado/fechas proMX se ignoran en Malcolm",""),IF(BF10="Cancelled","Cancelado: excluido de totales",IF(R10="","Sin estado: se trata como Draft",IF(BF10="Submitted",IF(ISNUMBER(V10),IF(V10>CFG_MAXD,"⚠ "&V10&" días en Submitted (máx. "&CFG_MAXD&")",""),"Falta fecha de envío"),IF(BF10="Returned","⚠ Devuelto: corregir y reenviar",IF(BF10="Recall Requested","Retirada solicitada: pendiente",IF(AND(BF10="Approved",NOT(ISNUMBER(T10))),"Falta fecha de aprobación",IF(AND(ISNUMBER(S10),ISNUMBER(T10),T10<S10),"Aprobación anterior al envío",""))))))))) | Y10: =IF(COUNTA(B10,D10,E10,F10,G10,H10,I10,J10,R10,S10,T10)>0,1,0) -> 1 | Z10: =IF(AND(ISNUMBER(H10),H10>=0,H10<1),ROUND(H10*1440,0),"") -> 780 | AA10: =IF(AND(ISNUMBER(I10),I10>=0,I10<1),ROUND(I10*1440,0),"") -> 860 | AB10: =IF(AND(ISNUMBER(B10),D10<>"",ISNUMBER(Z10),ISNUMBER(AA10)),IF(Z10=AA10,0,1),0) -> 1 | AC10: =IF(AB10=1,IF(AA10<Z10,1,0),0) -> 0 | AD10: =IF(AB10=1,IF(AC10=1,1440-Z10+AA10,AA10-Z10),0) -> 80 | AE10: =IF(J10="",0,IF(ISNUMBER(J10),J10,-1)) -> 0 | AF10: =MIN(MAX(0,AE10),AD10) -> 0 | AG10: =MAX(0,AD10-MAX(0,AE10)) -> 80 | AH10: =IF(ISNUMBER(B10),IF(AND(INDEX(CFG_WDAYS,WEEKDAY(INT(B10),2))="Sí",IF(D10="proMX",COUNTIFS(FER_F,INT(B10),FER_NLP,"Sí"),COUNTIFS(FER_F,INT(B10),FER_NLM,"Sí"))=0),1,0),0) -> 1 | AI10: =IF(AC10=1,IF(AND(INDEX(CFG_WDAYS,WEEKDAY(INT(B10)+1,2))="Sí",IF(D10="proMX",COUNTIFS(FER_F,INT(B10)+1,FER_NLP,"Sí"),COUNTIFS(FER_F,INT(B10)+1,FER_NLM,"Sí"))=0),1,0),0) -> 0 | AJ10: =IF(AC10=1,1440-Z10,AD10) -> 80 | AK10: =IF(AND(AB10=1,AH10=1),MAX(0,MIN(IF(AC10=1,1440,AA10),CFG_WEM)-MAX(Z10,CFG_WSM)),0) -> 80 | AL10: =IF(AND(AC10=1,AI10=1),MAX(0,MIN(AA10,CFG_WEM)-CFG_WSM),0) -> 0 | AM10: =AK10+AL10 -> 80 | AN10: =IF(CFG_BRK="Proporcional",IF(AD10=0,0,AF10*AM10/AD10),IF(CFG_BRK="Extras primero",MIN(AM10,MAX(0,AF10-(AD10-AM10))),MIN(AF10,AM10))) -> 0 | AO10: =AF10-AN10 -> 0 | AP10: =AM10-AN10 -> 80 | AQ10: =AD10-AM10-AO10 -> 0 | AR10: =IF(AM10=0,0,AK10-AN10*AK10/AM10) -> 80 | AS10: =IF(AD10-AM10=0,0,(AJ10-AK10)-AO10*(AJ10-AK10)/(AD10-AM10)) -> 0 | AT10: =IF(AC10=1,INT(B10)+1,"") | AU10: =IF(AND(D10="proMX",R10="Cancelled"),0,1) -> 1 | AV10: =IF(AND(AB10=1,AU10=1),IF(COUNTIFS($D$5:D9,D10,$B$5:B9,B10,$Z$5:Z9,Z10,$AA$5:AA9,AA10,$F$5:F9,F10&"",$AU$5:AU9,1)>0,1,0),0) -> 0 | AW10: =IF(AB10=1,INT(B10)*1440+Z10,"") -> 66672780 | AX10: =IF(AB10=1,AW10+AD10,"") -> 66672860 | AY10: =IF(AND(AB10=1,AV10=0,AU10=1),1,0) -> 1 | AZ10: =IF(AY10=1,COUNTIFS(R_Emp,D10,R_SAbs,"<"&AX10,R_EAbs,">"&AW10,R_OKey,1)-1,0) -> 0 | BA10: =IF(AY10=1,COUNTIFS(R_Emp,"<>"&D10,R_SAbs,"<"&AX10,R_EAbs,">"&AW10,R_OKey,1),0) -> 0 | BB10: =IF(AND(AB10=1,D10="proMX"),IF(AND(MOD(Z10,CFG_BLK)=0,MOD(AA10,CFG_BLK)=0,MOD(AG10,CFG_BLK)=0,AG10>0),1,0),1) -> 1 | BC10: =IF(Y10=0,"",IF(NOT(ISNUMBER(B10)),"Falta fecha o fecha inválida",IF(D10="","Falta empresa",IF(AND(D10<>"Malcolm",D10<>"proMX"),"Empresa inválida",IF(OR(INT(B10)<CFG_PSTART,INT(B10)>CFG_PEND),"Fecha fuera del período",IF(OR(NOT(ISNUMBER(Z10)),NOT(ISNUMBER(AA10))),"Falta hora inicio/fin o formato inválido",IF(AB10=0,"Hora inicio = hora fin",IF(AE10<0,"Descanso inválido",IF(AE10>=AD10,"Descanso ≥ duración",IF(AV10=1,"Registro duplicado",IF(AZ10>0,"Se superpone con otro registro "&D10,IF(BB10=0,"inicio, fin y duración neta deben ser múltiplos de "&CFG_BLK&" min","")))))))))))) | BD10: =IF(AND(Y10=1,BC10=""),1,0) -> 1 | BE10: =IF(AND(BD10=1,AU10=1),1,0) -> 1 | BF10: =IF(AND(D10="proMX",BD10=1),IF(R10="","Draft",R10),"") | BG10: =IF(BD10=1,ROUND(AG10/60,6),0) -> 1.333333 | BH10: =IF(BE10=1,ROUND(AG10/60,6),0) -> 1.333333 | BI10: =IF(BE10=1,ROUND(AP10/60,6),0) -> 1.333333 | BJ10: =IF(BE10=1,ROUND(AQ10/60,6),0) -> 0 | BK10: =IF(BE10=1,ROUND((AR10+AS10)/60,6),0) -> 1.333333 | BL10: =ROUND(BH10-BK10,6) -> 0 | BM10: =IF(BE10=1,ROUND(AR10/60,6),0) -> 1.333333 | BN10: =ROUND(BI10-BM10,6) -> 0 | BO10: =IF(BE10=1,ROUND(AS10/60,6),0) -> 0 | BP10: =ROUND(BJ10-BO10,6) -> 0 | BQ10: =IF(BE10=1,AW10,0) -> 66672780 | BR10: =IF(BE10=1,AX10,0) -> 66672860 | BS10: =IF(AND(BE10=1,D10="Malcolm",BA10>0),MIN(BH10,SUMPRODUCT((R_Emp="proMX")*(R_EN>0)*((R_EN-(R_EN>BR10)*(R_EN-BR10))>(R_SN+(R_SN<BQ10)*(BQ10-R_SN)))*((R_EN-(R_EN>BR10)*(R_EN-BR10))-(R_SN+(R_SN<BQ10)*(BQ10-R_SN))))/60),0) -> 0 | BT10: =IF(AND(BE10=1,D10="proMX"),ROUND(BI10*CFG_RATE+BJ10*CFG_OTRATE,6),0) -> 0 | BU10: =IF(AND(BD10=1,D10="proMX"),ROUND(AG10/CFG_BLK,6),0) -> 0 | BV10: =IF(BF10="Approved",IF(ISNUMBER(T10),INT(T10),INT(B10)),"") | BW10: =IF(ISNUMBER(B10),IF(DB_MON="Todos",1,IF(AND(INT(B10)>=DB_MS,INT(B10)<=DB_ME),1,0)),0) -> 1 | BX10: =IF(DB_PROJ="Todos",1,IF(E10&""=DB_PROJ&"",1,0)) -> 1 | BY10: =BW10*BX10 -> 1 | BZ10: =IF(Y10=1,F10&IF(AND(F10&""<>"",E10&""<>"")," · ","")&E10,"") -> PCF-102 · PCF | CA10: =IF(AND(BD10=1,E10&""<>""),IF(COUNTIFS($E$5:E9,E10,$BD$5:BD9,1)=0,MAX($CA$5:CA9)+1,""),"") | CB10: =IF(AND(BE10=1,D10="Malcolm",E10&""<>""),IF(COUNTIFS($D$5:D9,"Malcolm",$E$5:E9,E10,$BE$5:BE9,1)=0,MAX($CB$5:CB9)+1,""),"") | CC10: =IF(AND(BD10=1,D10="proMX",E10&""<>""),IF(COUNTIFS($D$5:D9,"proMX",$E$5:E9,E10,$BD$5:BD9,1)=0,MAX($CC$5:CC9)+1,""),"") | CD10: =IF(AND(BE10=1,D10="Malcolm",F10&""<>""),IF(COUNTIFS($D$5:D9,"Malcolm",$F$5:F9,F10,$BE$5:BE9,1)=0,MAX($CD$5:CD9)+1,""),"") -> 2 | CE10: =IF(AND(BD10=1,D10="proMX",F10&""<>""),IF(COUNTIFS($D$5:D9,"proMX",$F$5:F9,F10,$BD$5:BD9,1)=0,MAX($CE$5:CE9)+1,""),"") | CF10: =IF(AND(D10="proMX",BD10=1),IF(OR(BF10="Draft",BF10="Submitted",BF10="Returned",BF10="Recall Requested"),MAX($CF$5:CF9)+1,""),"") | CG10: =IF(BD10=0,0,IF(D10="Malcolm",1,MATCH(BF10,{"Draft","Submitted","Approved","Returned","Recall Requested","Cancelled"},0)+1)) -> 1 | CH10: =IF(AND(BF10="Submitted",ISNUMBER(V10)),IF(V10>CFG_MAXD,1,0),0) -> 0
